Workbook

Sheet Invoice
B1: FRESCOONE Trading Sdn Bhd
B2: 202301048876 (1542790-P)
B3: B-G-13 Block B Menara Alpha Jalan 4A/27A
B4: Seksyen 2 Wangsa Maju, 53300 Kuala Lumpur
B5: Tel: 011-21267669 Email: frescoone2020@gmail.com
B7: TAX INVOICE
B9: Invoice No: | C9: INV-SCON6-2026
B10: Invoice Date: | C10: 2026-07-16
B11: Billing Period: | C11: 1 June 2026 - 30 June 2026
B12: Platform / Channel: | C12: Shopee Malaysia (Case On Store — caseon123)
B14: Bill To:
B15: Case On Mobile phone Accessories Store
B16: No 4, Taman Seri Mangga, 4, Jalan Sri Mangga
B17: Reseller Code: SCON (Shopee Malaysia)
B19: Description | C19: Qty (Units) | D19: Amount (RM)
B20: Dropship Stock Charges — DSP Reseller Price (see "Itemized Calculation" tab, 666 order lines, June 2026 Completed orders) | C20: =SUM('Itemized Calculation'!F2:F667) -> 783 | D20: =SUM('Itemized Calculation'!K2:K667) -> 12941.351
B21: Subtotal | D21: =D20 -> 12941.351
B22: Less: Shopee Ads Rebate (70% of RM 362.00 ads spend — June 2026) | D22: =-362*0.7 -> -253.4
B23: Less: Approved Claims (see "Claims" tab) | D23: =-Claims!F46 -> 0
B24: TOTAL AMOUNT DUE (RM) | D24: =D21+D22+D23 -> 12687.951
B26: Payment Details
B27: Payable to: | C27: Frescoone Trading Sdn. Bhd
B28: Bank: | C28: OCBC Bank (Malaysia) Berhad
B29: Account No.: | C29: 7011620649
B31: Notes:
B32: 1. DSP = Dropship Price charged by FRESCOONE Trading Sdn Bhd to reseller for stock fulfilled via dropship.
B33: 2. Amounts reflect Completed orders only for June 2026, matched via Sitegiant order export (SGO) against Shopee order report (SO). 621/621 orders tally 100%.
B34: 3. 4 order lines are pending a manually keyed-in DSP price — see "Pending DSP Entry" tab. Totals here update automatically once entered.
B35: 4. Shopee Ads Rebate = 70% x total ads expense per Shopee-Ads-Overall-Data report for the period.
B36: 5. See "Order-Level Summary" tab for a per-order breakdown of Shopee income received vs. DSP charge owed vs. reseller net earning.
B37: 6. See "Returns & Refunds" tab for parcel return/refund cases and payment status, covering the past 3 months of Shopee balance history.
B38: 7. Promo Rate applied on each line has been verified against the reseller's actual Shopee retail discount (see "Itemized Calculation" tab, columns N-O) — full DSP is charged wherever no promotion was actually run.
B39: 8. See "Claims" tab to submit any claim for credit relating to a wrong item, product defect, or shipping issue — approved claims are credited above.
B40: 9. See "Returns & Refunds" tab, Section A, for the return-credit review workflow — once a row is marked "Confirmed Good — Remove Charge", the DSP charge for that order is removed directly in the "Itemized Calculation" tab (column K) and flows through automatically to the Dropship Stock Charges line above; it is not shown as a separate deduction here.

Sheet Pending DSP Entry
A1: PENDING TASKS — ALL ITEMS NEEDING YOUR INPUT / DECISION
A2: Work through each section below. Everything you key in or decide here flows automatically into "Itemized Calculation", the Invoice, and the Dashboard.
A4: A. MISSING DSP PRICE — 4 lines: SKU not found in DSP master. Key in DSP Price (col F). Fix/edit SKU (col D) and DSP + Promo Rate auto-fill if the SKU exists in the master.
A5: Ref No. | B5: Order ID | C5: Marketplace Order ID | D5: SKU (editable) | E5: Qty | F5: DSP Price (RM) — KEY IN | G5: SO Original (RM) | H5: SO Deal (RM) — Actual Promo Price | I5: SO Actual Disc % | J5: Table Promo Rate (auto) | K5: Verification Status | L5: Promo Applied? (Yes/No) | M5: Note
A6: 96 | B6: 225175 | C6: 2606047B8BX3BS | D6: LEEU-PC-LION-i11PRO-TP | E6: 1 | F6: =IFERROR(VLOOKUP(D6,'DSP Lookup'!A:B,2,FALSE()),"") -> 12.3 | G6: 15.9 | H6: 11.1 | I6: 0.3019 | J6: =IFERROR(VLOOKUP(D6,'DSP Lookup'!A:C,3,FALSE()),0) -> 0.3 | K6: Correct | L6: Yes | M6: ISKU not in DSP master — key in DSP price
A7: 558 | B7: 228827 | C7: 2606263WF5VB86 | D7: 7TREE-PC-JJ-ZFold7-BLU | E7: 1 | F7: 49.5 | G7: 67.9 | H7: 67.9 | I7: 0 | J7: =IFERROR(VLOOKUP(D7,'DSP Lookup'!A:C,3,FALSE()),0) -> 0 | K7: No Promotion Set | L7: No | M7: ISKU not in DSP master — key in DSP price
A8: 561 | B8: 228863 | C8: 26062649NPVTD3 | D8: 7TREE-PC-JJ-ZFold7-BLU | E8: 1 | F8: 49.5 | G8: 67.9 | H8: 67.9 | I8: 0 | J8: =IFERROR(VLOOKUP(D8,'DSP Lookup'!A:C,3,FALSE()),0) -> 0 | K8: No Promotion Set | L8: No | M8: ISKU not in DSP master — key in DSP price
A9: 627 | B9: 229416 | C9: 260629BQGAPD7R | D9: 7TREE-PC-JJ-ZFold7-BLU | E9: 1 | F9: 49.5 | G9: 67.9 | H9: 67.9 | I9: 0 | J9: =IFERROR(VLOOKUP(D9,'DSP Lookup'!A:C,3,FALSE()),0) -> 0 | K9: No Promotion Set | L9: No | M9: ISKU not in DSP master — key in DSP price
A11: B. MISSING SKU LINK IN SITEGIANT — 14 lines had a blank isku in Sitegiant; auto-matched via the Shopee SO SKU instead. Priced & invoiced already. Confirm each, and fix the isku linking in Sitegiant to prevent recurrence.
A12: Ref No. | B12: Order ID | C12: Marketplace Order ID | D12: SKU (recovered from SO) | E12: Qty | F12: DSP Price (RM) | G12: SO Original (RM) | H12: SO Deal (RM) | I12: SO Actual Disc % | J12: Table Promo Rate | K12: Verification Status | L12: Your Check (dropdown) | M12: Note
A13: 40 | B13: 224841 | C13: 2606022XU94PSF | D13: JJT-FILM-5A+-MB-BR | E13: 1 | F13: 15.5 | G13: 19.9 | H13: 18.9 | I13: 0.0503 | J13: 0.05 | K13: Correct | L13: Confirmed OK | M13: Sitegiant isku was blank — add the SKU link in Sitegiant
A14: 110 | B14: 225275 | C14: 2606058D74KNBG | D14: JJT-FILM-5A+-MB-CLR | E14: 1 | F14: 15.7 | G14: 19.9 | H14: 18.9 | I14: 0.0503 | J14: 0.05 | K14: Correct | L14: Confirmed OK | M14: Sitegiant isku was blank — add the SKU link in Sitegiant
A15: 121 | B15: 225327 | C15: 2606059M9SGXG3 | D15: JJT-FILM-5A+-MB-CLR | E15: 1 | F15: 15.7 | G15: 19.9 | H15: 18.9 | I15: 0.0503 | J15: 0.05 | K15: Correct | L15: Confirmed OK | M15: Sitegiant isku was blank — add the SKU link in Sitegiant
A16: 123 | B16: 225334 | C16: 2606059PQW3G74 | D16: JJT-FILM-5A+-MB-CLR | E16: 1 | F16: 15.7 | G16: 19.9 | H16: 18.9 | I16: 0.0503 | J16: 0.05 | K16: Correct | L16: Confirmed OK | M16: Sitegiant isku was blank — add the SKU link in Sitegiant
A17: 140 | B17: 225586 | C17: 260606C7JFDHF4 | D17: JJT-FILM-5A+-MB-BR | E17: 1 | F17: 15.5 | G17: 19.9 | H17: 18.9 | I17: 0.0503 | J17: 0.05 | K17: Correct | L17: Confirmed OK | M17: Sitegiant isku was blank — add the SKU link in Sitegiant
A18: 153 | B18: 225682 | C18: 260606D9DTFAW6 | D18: JJT-FILM-5A+-MB-CLR | E18: 1 | F18: 15.7 | G18: 19.9 | H18: 18.9 | I18: 0.0503 | J18: 0.05 | K18: Correct | L18: Confirmed OK | M18: Sitegiant isku was blank — add the SKU link in Sitegiant
A19: 171 | B19: 225866 | C19: 260607FJ45A7HT | D19: JJT-FILM-5A+-MB-MAT | E19: 1 | F19: 17.1 | G19: 21.9 | H19: 20.8 | I19: 0.0502 | J19: 0.05 | K19: Correct | L19: Confirmed OK | M19: Sitegiant isku was blank — add the SKU link in Sitegiant
A20: 390 | B20: 227355 | C20: 2606168DECAPAF | D20: JJT-FILM-5A+-MB-CLR | E20: 1 | F20: 15.7 | G20: 19.9 | H20: 18.9 | I20: 0.0503 | J20: 0.05 | K20: Correct | L20: Confirmed OK | M20: Sitegiant isku was blank — add the SKU link in Sitegiant
A21: 421 | B21: 227602 | C21: 260618DBEGWYYF | D21: JJT-FILM-5A+-MB-CLR | E21: 1 | F21: 15.7 | G21: 19.9 | H21: 18.9 | I21: 0.0503 | J21: 0.05 | K21: Correct | L21: Confirmed OK | M21: Sitegiant isku was blank — add the SKU link in Sitegiant
A22: 422 | B22: 227602 | C22: 260618DBEGWYYF | D22: JJT-FILM-5A+-MB-CLR | E22: 1 | F22: 15.7 | G22: 19.9 | H22: 18.9 | I22: 0.0503 | J22: 0.05 | K22: Correct | L22: Confirmed OK | M22: Sitegiant isku was blank — add the SKU link in Sitegiant
A23: 483 | B23: 228178 | C23: 260622QB750M9M | D23: JJT-FILM-5A+-TBL-CLR | E23: 1 | F23: 35.3 | G23: 44.9 | H23: 41.3 | I23: 0.0802 | J23: 0.08 | K23: Correct | L23: Confirmed OK | M23: Sitegiant isku was blank — add the SKU link in Sitegiant
A24: 589 | B24: 229119 | C24: 2606277V2Q13KR | D24: JJT-FILM-5A+-MB-MAT | E24: 1 | F24: 17.1 | G24: 21.9 | H24: 20.8 | I24: 0.0502 | J24: 0.05 | K24: Correct | L24: Confirmed OK | M24: Sitegiant isku was blank — add the SKU link in Sitegiant
... A26: 648 | B26: 229644 | C26: 260630EEJKKE4A | D26: JJT-FILM-5A+-MB-MAT | E26: 1 | F26: 17.1 | G26: 21.9 | H26: 20.8 | I26: 0.0502 | J26: 0.05 | K26: Correct | L26: Confirmed OK | M26: Sitegiant isku was blank — add the SKU link in Sitegiant
A28: C. MISSING PROMOTION RATE — 1 line(s): reseller ran a retail discount but the SKU has NO rate in the June Promo Rate table. Currently charged FULL DSP. Key in a rate (col J) to grant the discount; leave 0% to keep full DSP.
A29: Ref No. | B29: Order ID | C29: Marketplace Order ID | D29: SKU | E29: Qty | F29: DSP Price (RM) | G29: SO Original (RM) | H29: SO Deal (RM) | I29: SO Actual Disc % | J29: Promo Rate — KEY IN (0% = full DSP) | K29: Verification Status | L29: (auto) Applied? | M29: Note
A30: 38 | B30: 224834 | C30: 2606022WUSYU98 | D30: ESM-PC-DD-iP16ProMax-BLU | E30: 1 | F30: 14.9 | G30: 24.9 | H30: 24.16 | I30: 0.0297 | J30: 0.03 | K30: No Promo Rate On File | L30: =IF(J30=0,"No","Yes") -> Yes | M30: Add this SKU to the Promo Rate file if a rate should apply going forward
A32: D. INCORRECT PROMOTION RATE SET BY RESELLER — 70 lines: reseller ran a discount but NOT at our table rate. Default = still charge our table rate. Change the Decision (col L) to charge full DSP instead for any line.
A33: Ref No. | B33: Order ID | C33: Marketplace Order ID | D33: SKU | E33: Qty | F33: DSP Price (RM) | G33: SO Original (RM) | H33: SO Deal (RM) | I33: SO Actual Disc % (what they set) | J33: Our Table Rate (what they should set) | K33: Verification Status | L33: Decision (dropdown) | M33: Rate Difference
A34: 397 | B34: 227437 | C34: 260617ACGWMS94 | D34: DUX-IC-MAGI-TabS10Plus-BLK | E34: 1 | F34: 53.3 | G34: 69.9 | H34: 48.9 | I34: 0.3004 | J34: 0.03 | K34: WRONG RATE | L34: OK — Charge Table Rate | M34: =I34-J34 -> 0.2704
A35: 380 | B35: 227296 | C35: 260616748B40WY | D35: DUX-PC-AIMO-Mi14T-BLK | E35: 1 | F35: 15.8 | G35: 24.9 | H35: 14.89 | I35: 0.402 | J35: 0.2 | K35: WRONG RATE | L35: OK — Charge Table Rate | M35: =I35-J35 -> 0.202
A36: 584 | B36: 229108 | C36: 2606277REYYCC2 | D36: ZFRI-SP-GOR-i16ProMax-MAT | E36: 1 | F36: 15 | G36: 20.9 | H36: 19.64 | I36: 0.0603 | J36: 0.01 | K36: WRONG RATE | L36: OK — Charge Table Rate | M36: =I36-J36 -> 0.0503
A37: 625 | B37: 229396 | C37: 260629BK2XERY7 | D37: ZFRI-SP-GOR-i16ProMax-MAT | E37: 2 | F37: 15 | G37: 20.9 | H37: 19.64 | I37: 0.0603 | J37: 0.01 | K37: WRONG RATE | L37: OK — Charge Table Rate | M37: =I37-J37 -> 0.0503
A38: 129 | B38: 225396 | C38: 260605A4C418BR | D38: ZFRI-SP-GOR-i16ProMax-MAT | E38: 1 | F38: 15 | G38: 20.9 | H38: 19.84 | I38: 0.0507 | J38: 0.01 | K38: WRONG RATE | L38: OK — Charge Table Rate | M38: =I38-J38 -> 0.0407
A39: 309 | B39: 226794 | C39: 260613VHQWS67X | D39: ZFRI-SP-GOR-i16ProMax-MAT | E39: 1 | F39: 15 | G39: 20.9 | H39: 19.84 | I39: 0.0507 | J39: 0.01 | K39: WRONG RATE | L39: OK — Charge Table Rate | M39: =I39-J39 -> 0.0407
A40: 406 | B40: 227479 | C40: 260617B3HDSYTW | D40: ZFRI-SP-GOR-i16ProMax-MAT | E40: 1 | F40: 15 | G40: 20.9 | H40: 19.84 | I40: 0.0507 | J40: 0.01 | K40: WRONG RATE | L40: OK — Charge Table Rate | M40: =I40-J40 -> 0.0407
A41: 504 | B41: 228281 | C41: 260622RE3ER225 | D41: ZFRI-SP-GOR-i16ProMax-MAT | E41: 1 | F41: 15 | G41: 20.9 | H41: 19.84 | I41: 0.0507 | J41: 0.01 | K41: WRONG RATE | L41: OK — Charge Table Rate | M41: =I41-J41 -> 0.0407
A42: 98 | B42: 225182 | C42: 2606047DB35JBV | D42: ZFRI-LC-MbookAir/13(20)-CLR | E42: 1 | F42: 31.5 | G42: 39.9 | H42: 37.89 | I42: 0.0504 | J42: 0.01 | K42: WRONG RATE | L42: OK — Charge Table Rate | M42: =I42-J42 -> 0.0404
A43: 353 | B43: 227155 | C43: 2606155KB0B2U8 | D43: ZFRI-LC-MbookAir/13(20)-BLK | E43: 1 | F43: 31.5 | G43: 39.9 | H43: 37.89 | I43: 0.0504 | J43: 0.01 | K43: WRONG RATE | L43: OK — Charge Table Rate | M43: =I43-J43 -> 0.0404
A44: 522 | B44: 228426 | C44: 260623TTYET8VP | D44: ZFRI-LC-MbookAir/13(20)-BLK | E44: 1 | F44: 31.5 | G44: 39.9 | H44: 37.89 | I44: 0.0504 | J44: 0.01 | K44: WRONG RATE | L44: OK — Charge Table Rate | M44: =I44-J44 -> 0.0404
A45: 537 | B45: 228647 | C45: 260625145WAYM8 | D45: ZFRI-LC-MbookAir/13(20)-CLR | E45: 1 | F45: 31.5 | G45: 39.9 | H45: 37.89 | I45: 0.0504 | J45: 0.01 | K45: WRONG RATE | L45: OK — Charge Table Rate | M45: =I45-J45 -> 0.0404
...

Sheet Itemized Calculation
A1: No. | B1: Order ID | C1: Marketplace Order ID | D1: Order Date | E1: SKU | F1: Qty | G1: DSP Price (RM) | H1: Promo Rate (Our File) | I1: Promo Applied? | J1: Final Unit Price (RM) | K1: Line Total (RM) | L1: SO Original Price (RM) | M1: SO Deal Price (RM) — Actual Promo Price | N1: Reseller Actual Discount % (SO) | O1: Promo Verification Status | P1: Note | Q1: Original Line Total, Pre-Return Adj. (RM)
A2: 1 | B2: 224561 | C2: 260601UM8M25KH | D2: 2026-06-01 01:57 | E2: ZFRI-SP-GOR-i15-PVC | F2: 1 | G2: 13.2 | H2: 0.01 | I2: Yes | J2: =IF(G2="","",IF(I2="Yes",G2*(1-H2),G2)) -> 13.068 | K2: =IF(Q2="",0,IF(SUMPRODUCT(('Returns & Refunds'!$A$6:$A$11=C2)*('Returns & Refunds'!$H$6:$H$11="Confirmed Good — Remove Charge"))>0,0,Q2)) -> 13.068 | L2: 17.9 | M2: 17.7 | N2: 0.0112 | O2: Correct | Q2: =IF(J2="",0,F2*J2) -> 13.068
A3: 2 | B3: 224563 | C3: 260601UMYJBUSK | D3: 2026-06-01 02:10 | E3: ZFRI-SP-GOR-i13ProMax-PVC | F3: 1 | G3: 13.1 | H3: 0.01 | I3: Yes | J3: =IF(G3="","",IF(I3="Yes",G3*(1-H3),G3)) -> 12.969 | K3: =IF(Q3="",0,IF(SUMPRODUCT(('Returns & Refunds'!$A$6:$A$11=C3)*('Returns & Refunds'!$H$6:$H$11="Confirmed Good — Remove Charge"))>0,0,Q3)) -> 12.969 | L3: 17.9 | M3: 17.7 | N3: 0.0112 | O3: Correct | Q3: =IF(J3="",0,F3*J3) -> 12.969
A4: 3 | B4: 224565 | C4: 260601UN5QTNR6 | D4: 2026-06-01 02:14 | E4: ZFRI-SP-GOR-i17ProMax-PVC | F4: 1 | G4: 12.4 | H4: 0.01 | I4: Yes | J4: =IF(G4="","",IF(I4="Yes",G4*(1-H4),G4)) -> 12.276 | K4: =IF(Q4="",0,IF(SUMPRODUCT(('Returns & Refunds'!$A$6:$A$11=C4)*('Returns & Refunds'!$H$6:$H$11="Confirmed Good — Remove Charge"))>0,0,Q4)) -> 12.276 | L4: 17.9 | M4: 17.7 | N4: 0.0112 | O4: Correct | Q4: =IF(J4="",0,F4*J4) -> 12.276
A5: 4 | B5: 224586 | C5: 260601VCDKH9EV | D5: 2026-06-01 09:10 | E5: ZFRI-SP-GOR-i17ProMax-MAT | F5: 1 | G5: 15 | H5: 0.01 | I5: Yes | J5: =IF(G5="","",IF(I5="Yes",G5*(1-H5),G5)) -> 14.85 | K5: =IF(Q5="",0,IF(SUMPRODUCT(('Returns & Refunds'!$A$6:$A$11=C5)*('Returns & Refunds'!$H$6:$H$11="Confirmed Good — Remove Charge"))>0,0,Q5)) -> 14.85 | L5: 20.9 | M5: 20.7 | N5: 0.0096 | O5: Correct | Q5: =IF(J5="",0,F5*J5) -> 14.85
A6: 5 | B6: 224593 | C6: 260601VF4UTGSW | D6: 2026-06-01 09:59 | E6: GKK-PC-MSTAND-MagicV2-BLK | F6: 1 | G6: 49.8 | H6: 0.03 | I6: No | J6: =IF(G6="","",IF(I6="Yes",G6*(1-H6),G6)) -> 49.8 | K6: =IF(Q6="",0,IF(SUMPRODUCT(('Returns & Refunds'!$A$6:$A$11=C6)*('Returns & Refunds'!$H$6:$H$11="Confirmed Good — Remove Charge"))>0,0,Q6)) -> 49.8 | L6: 67.9 | M6: 67.9 | N6: 0 | O6: No Promotion Set | Q6: =IF(J6="",0,F6*J6) -> 49.8
A7: 6 | B7: 224605 | C7: 260601VKQ4HD1A | D7: 2026-06-01 11:20 | E7: ZFRI-SP-GOR-i12ProMax-PVC | F7: 2 | G7: 13.1 | H7: 0.01 | I7: Yes | J7: =IF(G7="","",IF(I7="Yes",G7*(1-H7),G7)) -> 12.969 | K7: =IF(Q7="",0,IF(SUMPRODUCT(('Returns & Refunds'!$A$6:$A$11=C7)*('Returns & Refunds'!$H$6:$H$11="Confirmed Good — Remove Charge"))>0,0,Q7)) -> 25.938 | L7: 17.9 | M7: 17.7 | N7: 0.0112 | O7: Correct | Q7: =IF(J7="",0,F7*J7) -> 25.938
A8: 7 | B8: 224607 | C8: 260601VMHXUKV2 | D8: 2026-06-01 11:36 | E8: DUX-WAC-BSNES-S/22-BLK | F8: 1 | G8: 34.5 | H8: 0.1 | I8: Yes | J8: =IF(G8="","",IF(I8="Yes",G8*(1-H8),G8)) -> 31.05 | K8: =IF(Q8="",0,IF(SUMPRODUCT(('Returns & Refunds'!$A$6:$A$11=C8)*('Returns & Refunds'!$H$6:$H$11="Confirmed Good — Remove Charge"))>0,0,Q8)) -> 31.05 | L8: 49.9 | M8: 44.9 | N8: 0.1002 | O8: Correct | Q8: =IF(J8="",0,F8*J8) -> 31.05
A9: 8 | B9: 224615 | C9: 260601VNPUF848 | D9: 2026-06-01 11:56 | E9: ZFRI-SP-GOR-i11/XR-MAT | F9: 1 | G9: 14.8 | H9: 0.01 | I9: Yes | J9: =IF(G9="","",IF(I9="Yes",G9*(1-H9),G9)) -> 14.652 | K9: =IF(Q9="",0,IF(SUMPRODUCT(('Returns & Refunds'!$A$6:$A$11=C9)*('Returns & Refunds'!$H$6:$H$11="Confirmed Good — Remove Charge"))>0,0,Q9)) -> 14.652 | L9: 20.9 | M9: 20.7 | N9: 0.0096 | O9: Correct | Q9: =IF(J9="",0,F9*J9) -> 14.652
A10: 9 | B10: 224621 | C10: 260601VQCXD4MB | D10: 2026-06-01 12:26 | E10: ZFRI-SP-GOR-i16ProMax-CLR | F10: 3 | G10: 10.7 | H10: 0.01 | I10: =IF('Pending DSP Entry'!L89="Charge Full DSP Instead","No","Yes") -> Yes | J10: =IF(G10="","",IF(I10="Yes",G10*(1-H10),G10)) -> 10.593 | K10: =IF(Q10="",0,IF(SUMPRODUCT(('Returns & Refunds'!$A$6:$A$11=C10)*('Returns & Refunds'!$H$6:$H$11="Confirmed Good — Remove Charge"))>0,0,Q10)) -> 31.779 | L10: 15 | M10: 14.75 | N10: 0.0167 | O10: WRONG RATE | P10: ="Wrong rate set by reseller — decision at Pending DSP Entry section D, row 89" -> Wrong rate set by reseller — decision at Pending DSP Entry section D, row 89 | Q10: =IF(J10="",0,F10*J10) -> 31.779
A11: 10 | B11: 224627 | C11: 260601VSU10CR4 | D11: 2026-06-01 13:10 | E11: DUX-PC-FITT-ZFold6-GRY | F11: 1 | G11: 31.4 | H11: 0.2 | I11: Yes | J11: =IF(G11="","",IF(I11="Yes",G11*(1-H11),G11)) -> 25.12 | K11: =IF(Q11="",0,IF(SUMPRODUCT(('Returns & Refunds'!$A$6:$A$11=C11)*('Returns & Refunds'!$H$6:$H$11="Confirmed Good — Remove Charge"))>0,0,Q11)) -> 25.12 | L11: 44.9 | M11: 35.9 | N11: 0.2004 | O11: Correct | Q11: =IF(J11="",0,F11*J11) -> 25.12
A12: 11 | B12: 224640 | C12: 260601VYTQXH6F | D12: 2026-06-01 14:57 | E12: LEEU-PC-ABAG-i15Pro-CLR | F12: 1 | G12: 8.6 | H12: 0.15 | I12: Yes | J12: =IF(G12="","",IF(I12="Yes",G12*(1-H12),G12)) -> 7.31 | K12: =IF(Q12="",0,IF(SUMPRODUCT(('Returns & Refunds'!$A$6:$A$11=C12)*('Returns & Refunds'!$H$6:$H$11="Confirmed Good — Remove Charge"))>0,0,Q12)) -> 7.31 | L12: 12.9 | M12: 11 | N12: 0.1473 | O12: Correct | Q12: =IF(J12="",0,F12*J12) -> 7.31
A13: 12 | B13: 224648 | C13: 260601W290CG53 | D13: 2026-06-01 15:41 | E13: ZFRI-SP-GOR-i15Pro-PVC | F13: 1 | G13: 13.2 | H13: 0.01 | I13: Yes | J13: =IF(G13="","",IF(I13="Yes",G13*(1-H13),G13)) -> 13.068 | K13: =IF(Q13="",0,IF(SUMPRODUCT(('Returns & Refunds'!$A$6:$A$11=C13)*('Returns & Refunds'!$H$6:$H$11="Confirmed Good — Remove Charge"))>0,0,Q13)) -> 13.068 | L13: 17.9 | M13: 17.7 | N13: 0.0112 | O13: Correct | Q13: =IF(J13="",0,F13*J13) -> 13.068
A14: 13 | B14: 224650 | C14: 26060100HKTR8T | D14: 2026-06-01 16:09 | E14: KDZ-PC-DDR-S25Plus-BLK | F14: 1 | G14: 27.2 | H14: 0.25 | I14: No | J14: =IF(G14="","",IF(I14="Yes",G14*(1-H14),G14)) -> 27.2 | K14: =IF(Q14="",0,IF(SUMPRODUCT(('Returns & Refunds'!$A$6:$A$11=C14)*('Returns & Refunds'!$H$6:$H$11="Confirmed Good — Remove Charge"))>0,0,Q14)) -> 27.2 | L14: 37.9 | M14: 37.9 | N14: 0 | O14: No Promotion Set | Q14: =IF(J14="",0,F14*J14) -> 27.2
A15: 14 | B15: 224651 | C15: 26060100MEF3HR | D15: 2026-06-01 16:11 | E15: ZFRI-LC-MbookPro/13(20)-BLK | F15: 1 | G15: 31.5 | H15: 0.01 | I15: Yes | J15: =IF(G15="","",IF(I15="Yes",G15*(1-H15),G15)) -> 31.185 | K15: =IF(Q15="",0,IF(SUMPRODUCT(('Returns & Refunds'!$A$6:$A$11=C15)*('Returns & Refunds'!$H$6:$H$11="Confirmed Good — Remove Charge"))>0,0,Q15)) -> 31.185 | L15: 39.9 | M15: 39.5 | N15: 0.01 | O15: Correct | Q15: =IF(J15="",0,F15*J15) -> 31.185
A16: 15 | B16: 224654 | C16: 260601046VGVEP | D16: 2026-06-01 17:15 | E16: ZFRI-SP-GOR-i13-CLR | F16: 1 | G16: 10.5 | H16: 0.01 | I16: Yes | J16: =IF(G16="","",IF(I16="Yes",G16*(1-H16),G16)) -> 10.395 | K16: =IF(Q16="",0,IF(SUMPRODUCT(('Returns & Refunds'!$A$6:$A$11=C16)*('Returns & Refunds'!$H$6:$H$11="Confirmed Good — Remove Charge"))>0,0,Q16)) -> 10.395 | L16: 15 | M16: 14.9 | N16: 0.0067 | O16: Correct | Q16: =IF(J16="",0,F16*J16) -> 10.395
A17: 16 | B17: 224659 | C17: 260601074YA7N3 | D17: 2026-06-01 18:08 | E17: ZFRI-SP-GOR-i13ProMax-PVC | F17: 1 | G17: 13.1 | H17: 0.01 | I17: Yes | J17: =IF(G17="","",IF(I17="Yes",G17*(1-H17),G17)) -> 12.969 | K17: =IF(Q17="",0,IF(SUMPRODUCT(('Returns & Refunds'!$A$6:$A$11=C17)*('Returns & Refunds'!$H$6:$H$11="Confirmed Good — Remove Charge"))>0,0,Q17)) -> 12.969 | L17: 17.9 | M17: 17.7 | N17: 0.0112 | O17: Correct | Q17: =IF(J17="",0,F17*J17) -> 12.969
A18: 17 | B18: 224668 | C18: 2606010CHRPRSG | D18: 2026-06-01 19:44 | E18: ESM-GC-PCTPU-SOLED-RED/CARD | F18: 1 | G18: 18.4 | H18: 0.05 | I18: Yes | J18: =IF(G18="","",IF(I18="Yes",G18*(1-H18),G18)) -> 17.48 | K18: =IF(Q18="",0,IF(SUMPRODUCT(('Returns & Refunds'!$A$6:$A$11=C18)*('Returns & Refunds'!$H$6:$H$11="Confirmed Good — Remove Charge"))>0,0,Q18)) -> 17.48 | L18: 24.9 | M18: 23.7 | N18: 0.0482 | O18: Correct | Q18: =IF(J18="",0,F18*J18) -> 17.48
A19: 18 | B19: 224671 | C19: 2606010EK8UMH4 | D19: 2026-06-01 20:21 | E19: DUX-IC-DOMO-iPad10/10.9(22)-BLU | F19: 1 | G19: 37.3 | H19: 0.03 | I19: Yes | J19: =IF(G19="","",IF(I19="Yes",G19*(1-H19),G19)) -> 36.181 | K19: =IF(Q19="",0,IF(SUMPRODUCT(('Returns & Refunds'!$A$6:$A$11=C19)*('Returns & Refunds'!$H$6:$H$11="Confirmed Good — Remove Charge"))>0,0,Q19)) -> 36.181 | L19: 49.9 | M19: 48.4 | N19: 0.0301 | O19: Correct | Q19: =IF(J19="",0,F19*J19) -> 36.181
A20: 19 | B20: 224700 | C20: 2606010PSUPXVP | D20: 2026-06-01 22:48 | E20: DDC-WTF-AR-MbookPro/16(21)-CLR | F20: 1 | G20: 10.3 | H20: 0.05 | I20: Yes | J20: =IF(G20="","",IF(I20="Yes",G20*(1-H20),G20)) -> 9.785 | K20: =IF(Q20="",0,IF(SUMPRODUCT(('Returns & Refunds'!$A$6:$A$11=C20)*('Returns & Refunds'!$H$6:$H$11="Confirmed Good — Remove Charge"))>0,0,Q20)) -> 9.785 | L20: 15.9 | M20: 15.1 | N20: 0.0503 | O20: Correct | Q20: =IF(J20="",0,F20*J20) -> 9.785
A21: 20 | B21: 224717 | C21: 2606020VUDU2UD | D21: 2026-06-02 00:36 | E21: LEEU-PC-ARCY(MS)-iP17ProMax-CLR | F21: 1 | G21: 17.5 | H21: 0.05 | I21: Yes | J21: =IF(G21="","",IF(I21="Yes",G21*(1-H21),G21)) -> 16.625 | K21: =IF(Q21="",0,IF(SUMPRODUCT(('Returns & Refunds'!$A$6:$A$11=C21)*('Returns & Refunds'!$H$6:$H$11="Confirmed Good — Remove Charge"))>0,0,Q21)) -> 16.625 | L21: 24.9 | M21: 23.7 | N21: 0.0482 | O21: Correct | Q21: =IF(J21="",0,F21*J21) -> 16.625
A22: 21 | B22: 224717 | C22: 2606020VUDU2UD | D22: 2026-06-02 00:36 | E22: ZFRI-SP-GOR-i17ProMax-CLR | F22: 1 | G22: 11.3 | H22: 0.01 | I22: Yes | J22: =IF(G22="","",IF(I22="Yes",G22*(1-H22),G22)) -> 11.187 | K22: =IF(Q22="",0,IF(SUMPRODUCT(('Returns & Refunds'!$A$6:$A$11=C22)*('Returns & Refunds'!$H$6:$H$11="Confirmed Good — Remove Charge"))>0,0,Q22)) -> 11.187 | L22: 15.9 | M22: 15.7 | N22: 0.0126 | O22: Correct | Q22: =IF(J22="",0,F22*J22) -> 11.187
... A38: 37 | B38: 224833 | C38: 2606022WJ6W927 | D38: 2026-06-02 19:54 | E38: ZFRI-SP-GOR-i11ProMax-PVC | F38: 1 | G38: 13.1 | H38: 0.01 | I38: Yes | J38: =IF(G38="","",IF(I38="Yes",G38*(1-H38),G38)) -> 12.969 | K38: =IF(Q38="",0,IF(SUMPRODUCT(('Returns & Refunds'!$A$6:$A$11=C38)*('Returns & Refunds'!$H$6:$H$11="Confirmed Good — Remove Charge"))>0,0,Q38)) -> 12.969 | L38: 17.9 | M38: 17.7 | N38: 0.0112 | O38: Correct | Q38: =IF(J38="",0,F38*J38) -> 12.969
A39: 38 | B39: 224834 | C39: 2606022WUSYU98 | D39: 2026-06-02 19:59 | E39: ESM-PC-DD-iP16ProMax-BLU | F39: 1 | G39: 14.9 | H39: ='Pending DSP Entry'!J30 -> 0.03 | I39: =IF('Pending DSP Entry'!J30=0,"No","Yes") -> Yes | J39: =IF(G39="","",IF(I39="Yes",G39*(1-H39),G39)) -> 14.453 | K39: =IF(Q39="",0,IF(SUMPRODUCT(('Returns & Refunds'!$A$6:$A$11=C39)*('Returns & Refunds'!$H$6:$H$11="Confirmed Good — Remove Charge"))>0,0,Q39)) -> 14.453 | L39: 24.9 | M39: 24.16 | N39: 0.0297 | O39: No Promo Rate On File | P39: ="Rate pending your input — Pending DSP Entry section C, row 30" -> Rate pending your input — Pending DSP Entry section C, row 30 | Q39: =IF(J39="",0,F39*J39) -> 14.453
A40: 39 | B40: 224838 | C40: 2606022XFP4C58 | D40: 2026-06-02 20:10 | E40: ZFRI-SP-GOR-i12-PVC | F40: 1 | G40: 13.1 | H40: 0.01 | I40: No | J40: =IF(G40="","",IF(I40="Yes",G40*(1-H40),G40)) -> 13.1 | K40: =IF(Q40="",0,IF(SUMPRODUCT(('Returns & Refunds'!$A$6:$A$11=C40)*('Returns & Refunds'!$H$6:$H$11="Confirmed Good — Remove Charge"))>0,0,Q40)) -> 13.1 | L40: 17.9 | M40: 17.9 | N40: 0 | O40: No Promotion Set | Q40: =IF(J40="",0,F40*J40) -> 13.1
A41: 40 | B41: 224841 | C41: 2606022XU94PSF | D41: 2026-06-02 20:17 | E41: JJT-FILM-5A+-MB-BR | F41: 1 | G41: 15.5 | H41: 0.05 | I41: Yes | J41: =IF(G41="","",IF(I41="Yes",G41*(1-H41),G41)) -> 14.725 | K41: =IF(Q41="",0,IF(SUMPRODUCT(('Returns & Refunds'!$A$6:$A$11=C41)*('Returns & Refunds'!$H$6:$H$11="Confirmed Good — Remove Charge"))>0,0,Q41)) -> 14.725 | L41: 19.9 | M41: 18.9 | N41: 0.0503 | O41: Correct | Q41: =IF(J41="",0,F41*J41) -> 14.725
A42: 41 | B42: 224862 | C42: 26060235A9ARW3 | D42: 2026-06-02 22:13 | E42: 7TREE-PC-XF-MagicV5-GLD | F42: 1 | G42: 48.9 | H42: 0.02 | I42: No | J42: =IF(G42="","",IF(I42="Yes",G42*(1-H42),G42)) -> 48.9 | K42: =IF(Q42="",0,IF(SUMPRODUCT(('Returns & Refunds'!$A$6:$A$11=C42)*('Returns & Refunds'!$H$6:$H$11="Confirmed Good — Remove Charge"))>0,0,Q42)) -> 48.9 | L42: 67.9 | M42: 67.9 | N42: 0 | O42: No Promotion Set | Q42: =IF(J42="",0,F42*J42) -> 48.9
A43: 42 | B43: 224864 | C43: 260602360X377J | D43: 2026-06-02 22:25 | E43: FATB-GC-NSwitch-BLK | F43: 1 | G43: 64.8 | H43: 0.02 | I43: No | J43: =IF(G43="","",IF(I43="Yes",G43*(1-H43),G43)) -> 64.8 | K43: =IF(Q43="",0,IF(SUMPRODUCT(('Returns & Refunds'!$A$6:$A$11=C43)*('Returns & Refunds'!$H$6:$H$11="Confirmed Good — Remove Charge"))>0,0,Q43)) -> 64.8 | L43: 84.9 | M43: 84.9 | N43: 0 | O43: No Promotion Set | Q43: =IF(J43="",0,F43*J43) -> 64.8
A44: 43 | B44: 224864 | C44: 260602360X377J | D44: 2026-06-02 22:25 | E44: FATB-GC-CLAS-SwitchOLED-BLK | F44: 1 | G44: 64.8 | H44: 0.02 | I44: Yes | J44: =IF(G44="","",IF(I44="Yes",G44*(1-H44),G44)) -> 63.504 | K44: =IF(Q44="",0,IF(SUMPRODUCT(('Returns & Refunds'!$A$6:$A$11=C44)*('Returns & Refunds'!$H$6:$H$11="Confirmed Good — Remove Charge"))>0,0,Q44)) -> 63.504 | L44: 84.9 | M44: 83.2 | N44: 0.02 | O44: Correct | Q44: =IF(J44="",0,F44*J44) -> 63.504
A45: 44 | B45: 224876 | C45: 26060239BXR2GT | D45: 2026-06-02 23:25 | E45: ZFRI-SP-GOR-i14ProMax-CLR | F45: 2 | G45: 10.5 | H45: 0.01 | I45: Yes | J45: =IF(G45="","",IF(I45="Yes",G45*(1-H45),G45)) -> 10.395 | K45: =IF(Q45="",0,IF(SUMPRODUCT(('Returns & Refunds'!$A$6:$A$11=C45)*('Returns & Refunds'!$H$6:$H$11="Confirmed Good — Remove Charge"))>0,0,Q45)) -> 20.79 | L45: 15 | M45: 14.9 | N45: 0.0067 | O45: Correct | Q45: =IF(J45="",0,F45*J45) -> 20.79
A46: 45 | B46: 224878 | C46: 2606023AWT7TT8 | D46: 2026-06-02 23:53 | E46: 7TREE-PC-PU-Magic7Pro-WHT | F46: 1 | G46: 13.6 | H46: 0.1 | I46: Yes | J46: =IF(G46="","",IF(I46="Yes",G46*(1-H46),G46)) -> 12.24 | K46: =IF(Q46="",0,IF(SUMPRODUCT(('Returns & Refunds'!$A$6:$A$11=C46)*('Returns & Refunds'!$H$6:$H$11="Confirmed Good — Remove Charge"))>0,0,Q46)) -> 12.24 | L46: 19.9 | M46: 17.9 | N46: 0.1005 | O46: Correct | Q46: =IF(J46="",0,F46*J46) -> 12.24
A47: 46 | B47: 224881 | C47: 2606033BP4ENM3 | D47: 2026-06-03 00:07 | E47: LEEU-LANY-CLIMB-ADJ-BEI | F47: 1 | G47: 18.8 | H47: 0.01 | I47: Yes | J47: =IF(G47="","",IF(I47="Yes",G47*(1-H47),G47)) -> 18.612 | K47: =IF(Q47="",0,IF(SUMPRODUCT(('Returns & Refunds'!$A$6:$A$11=C47)*('Returns & Refunds'!$H$6:$H$11="Confirmed Good — Remove Charge"))>0,0,Q47)) -> 18.612 | L47: 24.9 | M47: 24.7 | N47: 0.008 | O47: Correct | Q47: =IF(J47="",0,F47*J47) -> 18.612
A48: 47 | B48: 224883 | C48: 2606033CYWF4NK | D48: 2026-06-03 00:30 | E48: OEM-SP-ARC-TabS7FE-CLR | F48: 1 | G48: 16.8 | H48: 0.03 | I48: Yes | J48: =IF(G48="","",IF(I48="Yes",G48*(1-H48),G48)) -> 16.296 | K48: =IF(Q48="",0,IF(SUMPRODUCT(('Returns & Refunds'!$A$6:$A$11=C48)*('Returns & Refunds'!$H$6:$H$11="Confirmed Good — Remove Charge"))>0,0,Q48)) -> 16.296 | L48: 23.9 | M48: 23.2 | N48: 0.0293 | O48: Correct | Q48: =IF(J48="",0,F48*J48) -> 16.296
A49: 48 | B49: 224888 | C49: 2606033EQQR98J | D49: 2026-06-03 01:01 | E49: ZFRI-SP-GOR-i16Pro-PVC | F49: 1 | G49: 13.5 | H49: 0.01 | I49: Yes | J49: =IF(G49="","",IF(I49="Yes",G49*(1-H49),G49)) -> 13.365 | K49: =IF(Q49="",0,IF(SUMPRODUCT(('Returns & Refunds'!$A$6:$A$11=C49)*('Returns & Refunds'!$H$6:$H$11="Confirmed Good — Remove Charge"))>0,0,Q49)) -> 13.365 | L49: 17.9 | M49: 17.7 | N49: 0.0112 | O49: Correct | Q49: =IF(J49="",0,F49*J49) -> 13.365
A50: 49 | B50: 224889 | C50: 2606033ERBSA1S | D50: 2026-06-03 01:02 | E50: ZFRI-LC-MbookPro/14(2021)-BLK | F50: 1 | G50: 41.5 | H50: 0.01 | I50: Yes | J50: =IF(G50="","",IF(I50="Yes",G50*(1-H50),G50)) -> 41.085 | K50: =IF(Q50="",0,IF(SUMPRODUCT(('Returns & Refunds'!$A$6:$A$11=C50)*('Returns & Refunds'!$H$6:$H$11="Confirmed Good — Remove Charge"))>0,0,Q50)) -> 41.085 | L50: 54.9 | M50: 54.4 | N50: 0.0091 | O50: Correct | Q50: =IF(J50="",0,F50*J50) -> 41.085
A51: 50 | B51: 224889 | C51: 2606033ERBSA1S | D51: 2026-06-03 01:02 | E51: DDC-LAC-KC-MbookAir/13(22)-CLR | F51: 1 | G51: 6.5 | H51: 0.05 | I51: Yes | J51: =IF(G51="","",IF(I51="Yes",G51*(1-H51),G51)) -> 6.175 | K51: =IF(Q51="",0,IF(SUMPRODUCT(('Returns & Refunds'!$A$6:$A$11=C51)*('Returns & Refunds'!$H$6:$H$11="Confirmed Good — Remove Charge"))>0,0,Q51)) -> 6.175 | L51: 9.9 | M51: 9.4 | N51: 0.0505 | O51: Correct | Q51: =IF(J51="",0,F51*J51) -> 6.175
... A77: 76 | B77: 225090 | C77: 2606045WVGPV4J | D77: 2026-06-04 00:38 | E77: XINC-LAC-VERS-Bag/12inch-BLK | F77: 1 | G77: 14.4 | H77: 0.01 | I77: Yes | J77: =IF(G77="","",IF(I77="Yes",G77*(1-H77),G77)) -> 14.256 | K77: =IF(Q77="",0,IF(SUMPRODUCT(('Returns & Refunds'!$A$6:$A$11=C77)*('Returns & Refunds'!$H$6:$H$11="Confirmed Good — Remove Charge"))>0,0,Q77)) -> 14.256 | L77: 19.9 | M77: 19.7 | N77: 0.0101 | O77: Correct | Q77: =IF(J77="",0,F77*J77) -> 14.256
A78: 77 | B78: 225093 | C78: 2606045XE2DUTX | D78: 2026-06-04 00:48 | E78: ZFRI-LC-MbookPro/13(20)-CLR | F78: 1 | G78: 31.5 | H78: 0.01 | I78: =IF('Pending DSP Entry'!L59="Charge Full DSP Instead","No","Yes") -> Yes | J78: =IF(G78="","",IF(I78="Yes",G78*(1-H78),G78)) -> 31.185 | K78: =IF(Q78="",0,IF(SUMPRODUCT(('Returns & Refunds'!$A$6:$A$11=C78)*('Returns & Refunds'!$H$6:$H$11="Confirmed Good — Remove Charge"))>0,0,Q78)) -> 31.185 | L78: 39.9 | M78: 39.11 | N78: 0.0198 | O78: WRONG RATE | P78: ="Wrong rate set by reseller — decision at Pending DSP Entry section D, row 59" -> Wrong rate set by reseller — decision at Pending DSP Entry section D, row 59 | Q78: =IF(J78="",0,F78*J78) -> 31.185
A79: 78 | B79: 225093 | C79: 2606045XE2DUTX | D79: 2026-06-04 00:48 | E79: DDC-WTF-AR-MbookAir/13(18)-CLR | F79: 1 | G79: 10 | H79: 0.05 | I79: =IF('Pending DSP Entry'!L61="Charge Full DSP Instead","No","Yes") -> Yes | J79: =IF(G79="","",IF(I79="Yes",G79*(1-H79),G79)) -> 9.5 | K79: =IF(Q79="",0,IF(SUMPRODUCT(('Returns & Refunds'!$A$6:$A$11=C79)*('Returns & Refunds'!$H$6:$H$11="Confirmed Good — Remove Charge"))>0,0,Q79)) -> 9.5 | L79: 15.9 | M79: 14.95 | N79: 0.0597 | O79: WRONG RATE | P79: ="Wrong rate set by reseller — decision at Pending DSP Entry section D, row 61" -> Wrong rate set by reseller — decision at Pending DSP Entry section D, row 61 | Q79: =IF(J79="",0,F79*J79) -> 9.5
A80: 79 | B80: 225093 | C80: 2606045XE2DUTX | D80: 2026-06-04 00:48 | E80: DDC-LAC-KC-MbookPro/13(22)-CLR | F80: 1 | G80: 6.5 | H80: 0.05 | I80: =IF('Pending DSP Entry'!L68="Charge Full DSP Instead","No","Yes") -> Yes | J80: =IF(G80="","",IF(I80="Yes",G80*(1-H80),G80)) -> 6.175 | K80: =IF(Q80="",0,IF(SUMPRODUCT(('Returns & Refunds'!$A$6:$A$11=C80)*('Returns & Refunds'!$H$6:$H$11="Confirmed Good — Remove Charge"))>0,0,Q80)) -> 6.175 | L80: 9.9 | M80: 9.31 | N80: 0.0596 | O80: WRONG RATE | P80: ="Wrong rate set by reseller — decision at Pending DSP Entry section D, row 68" -> Wrong rate set by reseller — decision at Pending DSP Entry section D, row 68 | Q80: =IF(J80="",0,F80*J80) -> 6.175
...

Sheet Order-Level Summary
A1: No. | B1: Marketplace Order ID | C1: Order Date | D1: Line Items | E1: Income Received (RM) [Shopee Payout - SB] | F1: Total DSP Charge (RM) [owed to FRESCOONE] | G1: Reseller Final Earning (RM) [Income - DSP Charge]
A2: 1 | B2: 260601UM8M25KH | C2: 2026-06-01 01:57 | D2: =COUNTIF('Itemized Calculation'!C:C,B2) -> 1 | E2: 13.43 | F2: =SUMIF('Itemized Calculation'!C:C,B2,'Itemized Calculation'!K:K) -> 13.068 | G2: =E2-F2 -> 0.362
A3: 2 | B3: 260601UMYJBUSK | C3: 2026-06-01 02:10 | D3: =COUNTIF('Itemized Calculation'!C:C,B3) -> 1 | E3: 13.14 | F3: =SUMIF('Itemized Calculation'!C:C,B3,'Itemized Calculation'!K:K) -> 12.969 | G3: =E3-F3 -> 0.171
A4: 3 | B4: 260601UN5QTNR6 | C4: 2026-06-01 02:14 | D4: =COUNTIF('Itemized Calculation'!C:C,B4) -> 1 | E4: 13.72 | F4: =SUMIF('Itemized Calculation'!C:C,B4,'Itemized Calculation'!K:K) -> 12.276 | G4: =E4-F4 -> 1.444
A5: 4 | B5: 260601VCDKH9EV | C5: 2026-06-01 09:10 | D5: =COUNTIF('Itemized Calculation'!C:C,B5) -> 1 | E5: 16.14 | F5: =SUMIF('Itemized Calculation'!C:C,B5,'Itemized Calculation'!K:K) -> 14.85 | G5: =E5-F5 -> 1.29
A6: 5 | B6: 260601VF4UTGSW | C6: 2026-06-01 09:59 | D6: =COUNTIF('Itemized Calculation'!C:C,B6) -> 1 | E6: 54.16 | F6: =SUMIF('Itemized Calculation'!C:C,B6,'Itemized Calculation'!K:K) -> 49.8 | G6: =E6-F6 -> 4.36
A7: 6 | B7: 260601VKQ4HD1A | C7: 2026-06-01 11:20 | D7: =COUNTIF('Itemized Calculation'!C:C,B7) -> 1 | E7: 27.41 | F7: =SUMIF('Itemized Calculation'!C:C,B7,'Itemized Calculation'!K:K) -> 25.938 | G7: =E7-F7 -> 1.472
A8: 7 | B8: 260601VMHXUKV2 | C8: 2026-06-01 11:36 | D8: =COUNTIF('Itemized Calculation'!C:C,B8) -> 1 | E8: 35.14 | F8: =SUMIF('Itemized Calculation'!C:C,B8,'Itemized Calculation'!K:K) -> 31.05 | G8: =E8-F8 -> 4.09
A9: 8 | B9: 260601VNPUF848 | C9: 2026-06-01 11:56 | D9: =COUNTIF('Itemized Calculation'!C:C,B9) -> 1 | E9: 16.14 | F9: =SUMIF('Itemized Calculation'!C:C,B9,'Itemized Calculation'!K:K) -> 14.652 | G9: =E9-F9 -> 1.488
A10: 9 | B10: 260601VQCXD4MB | C10: 2026-06-01 12:26 | D10: =COUNTIF('Itemized Calculation'!C:C,B10) -> 1 | E10: 35.11 | F10: =SUMIF('Itemized Calculation'!C:C,B10,'Itemized Calculation'!K:K) -> 31.779 | G10: =E10-F10 -> 3.331
A11: 10 | B11: 260601VSU10CR4 | C11: 2026-06-01 13:10 | D11: =COUNTIF('Itemized Calculation'!C:C,B11) -> 1 | E11: 28.38 | F11: =SUMIF('Itemized Calculation'!C:C,B11,'Itemized Calculation'!K:K) -> 25.12 | G11: =E11-F11 -> 3.26
A12: 11 | B12: 260601VYTQXH6F | C12: 2026-06-01 14:57 | D12: =COUNTIF('Itemized Calculation'!C:C,B12) -> 1 | E12: 8.14 | F12: =SUMIF('Itemized Calculation'!C:C,B12,'Itemized Calculation'!K:K) -> 7.31 | G12: =E12-F12 -> 0.83
A13: 12 | B13: 260601W290CG53 | C13: 2026-06-01 15:41 | D13: =COUNTIF('Itemized Calculation'!C:C,B13) -> 1 | E13: 13.15 | F13: =SUMIF('Itemized Calculation'!C:C,B13,'Itemized Calculation'!K:K) -> 13.068 | G13: =E13-F13 -> 0.082
... A563: 562 | B563: 260630FH5NP3TT | C563: 2026-06-30 23:50 | D563: =COUNTIF('Itemized Calculation'!C:C,B563) -> 1 | E563: 23.32 | F563: =SUMIF('Itemized Calculation'!C:C,B563,'Itemized Calculation'!K:K) -> 21.186 | G563: =E563-F563 -> 2.134
D564: TOTAL | E564: =SUM(E2:E563) -> 13839.02 | F564: =SUM(F2:F563) -> 12941.351 | G564: =SUM(G2:G563) -> 897.669
A566: Notes:
A567: Income Received = actual Shopee payout for that order, matched by Marketplace Order ID from the my_balance Transaction Report (SB), Money In minus any Money Out adjustments for that order.
A568: Total DSP Charge = sum of all Itemized Calculation line totals for that order (auto-updates as Pending DSP Entry rows are filled in).
A569: Reseller Final Earning = Income Received less Total DSP Charge owed to FRESCOONE — this is the reseller's margin on the order BEFORE their own Shopee ads spend / other costs.

Sheet Returns & Refunds
A1: RETURN / REFUND PARCEL CASES & PAYMENT STATUS
A2: Case On Store (caseon123) — Shopee balance history reviewed: 16 Apr 2026 to 16 Jul 2026 (past 3 months)
A4: A. June 2026 Orders Under Return/Refund (Shopee "Request Approved" status) — part of this invoice batch
A5: Order ID | B5: Product | C5: Qty | D5: Order Subtotal (RM) | E5: Refund Status (Shopee) | F5: Net Income Received to Date (RM) | G5: DSP Charged (RM) | H5: Frescoone Verified? (check Sitegiant, then decide) | I5: DSP Charge Removed (RM) | J5: Assessment
A6: 2606059UKM0Q6R | B6: CASEON GORILLA CLEAR PRIVACY Tempered Glass for iPhone 17 17e Air 16 16E 15 14 Plus 13 12 11 XS Pro Max XR Full Screen | C6: 1 | D6: 14.9 | E6: Request Approved | F6: -8.48 | G6: =SUMIF('Itemized Calculation'!C:C,A6,'Itemized Calculation'!Q:Q) -> 10.395 | H6: Confirmed Good — Remove Charge | I6: =IF(H6="Confirmed Good — Remove Charge",G6,0) -> 10.395 | J6: Refund clawed back in full via escrow reversal (reseller wallet debited)
A7: 260607FSSF1BQ6 | B7: DUX DUCIS SKIN X PRO Leather TPU Magnet Card Phone Case for iPhone 17 17e Air 16 15 14 13 Pro Max Plus Clear Flip Cover | C7: 1 | D7: 47.9 | E7: Request Approved | F7: 23.95 | G7: =SUMIF('Itemized Calculation'!C:C,A7,'Itemized Calculation'!Q:Q) -> 33.7 | H7: Confirmed Good — Remove Charge | I7: =IF(H7="Confirmed Good — Remove Charge",G7,0) -> 33.7 | J7: Return approved — clawback not yet posted in Shopee balance as of report date; monitor for future deduction
A8: 2606130KMN28WN | B8: ZIFRIEND SILK PRIVACY / CLEAR Tempered Glass For iPhone 16 16E 15 14 Plus 13 12 11 Pro Max XR Anti Spy Full Screen Tools | C8: 2 | D8: 26.53 | E8: Request Approved | F8: 60.09 | G8: =SUMIF('Itemized Calculation'!C:C,A8,'Itemized Calculation'!Q:Q) -> 90.88 | H8: Confirmed Good — Remove Charge | I8: =IF(H8="Confirmed Good — Remove Charge",G8,0) -> 90.88 | J8: Return approved — clawback not yet posted in Shopee balance as of report date; monitor for future deduction
A9: 2606130KMN28WN | B9: DUX DUCIS DOMO Sarung Tablet untuk iPad Pro 13 11 12.9 Mini 7 6 Air 13 11 5 4 3 /10 9 8 7 Leather TPU Case Cover Casing | C9: 2 | D9: 67 | E9: Request Approved | F9: 60.09 | G9: =SUMIF('Itemized Calculation'!C:C,A9,'Itemized Calculation'!Q:Q) -> 90.88 | H9: Confirmed Good — Remove Charge | I9: =IF(H9="Confirmed Good — Remove Charge",G9,0) -> 90.88 | J9: Return approved — clawback not yet posted in Shopee balance as of report date; monitor for future deduction
A10: 260617ASXPJMQF | B10: MAGNETIC FROSTED Matte / Clear PC TPU Dustproof Phone Case Oppo Reno 13 13F 12 12F A5 Pro 5G 4G Non Yellow Shockproof GB | C10: 2 | D10: 29.8 | E10: Request Approved | F10: -11.35 | G10: =SUMIF('Itemized Calculation'!C:C,A10,'Itemized Calculation'!Q:Q) -> 19.2 | H10: Confirmed Good — Remove Charge | I10: =IF(H10="Confirmed Good — Remove Charge",G10,0) -> 19.2 | J10: Refund clawed back in full via escrow reversal (reseller wallet debited)
A11: 260630F5NB9V5P | B11: ZIFRIEND MATTE Clear Ultra Slim Hard PC Case for MacBook Pro Air 13 14 15 16 inch M5 M4 M3 M2 M1 A2941 Case Casing Cover | C11: 1 | D11: 57.3 | E11: Request Approved | F11: -17.91 | G11: =SUMIF('Itemized Calculation'!C:C,A11,'Itemized Calculation'!Q:Q) -> 43.263 | H11: Confirmed Good — Remove Charge | I11: =IF(H11="Confirmed Good — Remove Charge",G11,0) -> 43.263 | J11: Refund clawed back in full via escrow reversal (reseller wallet debited)
B12: TOTAL DSP CHARGE REMOVED | I12: =SUM(I6:I11) -> 288.318
A13: Instructions: for each row, check Sitegiant to confirm the returned parcel was received back in good condition. Set column H to "Confirmed Good — Remove Charge" to remove the DSP charge for that order directly in the "Itemized Calculation" tab (column K), or "Not Returned / Keep Charge" if the item was not actually returned in good order. Leave as "Pending Review" until checked. Column G always shows the original DSP charge for reference, even after removal.
A15: B. All Return/Refund Escrow-Reversal Adjustments — full 3-month Shopee balance history
A16: Date | B16: Order ID | C16: Amount Clawed Back (RM) | D16: In This Invoice Batch (June)? | E16: Description
A17: 2026-07-15 00:47:13 | B17: 2607073KBUHB1H | C17: -199.48 | D17: No — prior month order | E17: Wallet adjustment for order 2607073KBUHB1H due to Return/Refund after escrow release
A18: 2026-07-15 00:45:42 | B18: 260630F5NB9V5P | C18: -62.91 | D18: Yes | E18: Wallet adjustment for order 260630F5NB9V5P due to Return/Refund after escrow release
A19: 2026-06-26 00:45:51 | B19: 260617ASXPJMQF | C19: -33.52 | D19: Yes | E19: Wallet adjustment for order 260617ASXPJMQF due to Return/Refund after escrow release
A20: 2026-05-31 00:47:15 | B20: 260518QHP81CRN | C20: -39.4 | D20: No — prior month order | E20: Wallet adjustment for order 260518QHP81CRN due to Return/Refund after escrow release
A21: 2026-05-23 14:49:39 | B21: 260503EBK407JU | C21: -55.3 | D21: No — prior month order | E21: Wallet adjustment for order 260503EBK407JU due to Return/Refund after escrow release
A22: 2026-05-18 19:21:02 | B22: 260513AGQ25WWW | C22: -18.02 | D22: No — prior month order | E22: Wallet adjustment for order 260513AGQ25WWW due to Return/Refund after escrow release
A23: 2026-05-13 14:46:35 | B23: 260507R1XYJABV | C23: -21.29 | D23: No — prior month order | E23: Wallet adjustment for order 260507R1XYJABV due to Return/Refund after escrow release
A24: 2026-04-30 20:47:47 | B24: 260410FAG4NAPC | C24: -63.42 | D24: No — prior month order | E24: Wallet adjustment for order 260410FAG4NAPC due to Return/Refund after escrow release
B25: TOTAL | C25: =SUM(C17:C24) -> -493.34
A27: C. Payment Status Check — Orders Not Yet Received from Platform
A28: Of 562 unique Completed June 2026 orders, 562 / 562 have at least one matching transaction in the 3-month Shopee balance report (100% — no orders missing a payout record as of 16 Jul 2026).
A29: 3 of these orders show a NEGATIVE net income (full refund already clawed back): 2606059UKM0Q6R (-RM8.48), 260617ASXPJMQF (-RM11.35), 260630F5NB9V5P (-RM17.91). See Section A above.
A30: Data limitation: only June 2026 order-level detail (SO/SGO) was provided, so this "not yet paid" check is only conclusive for June orders. April/May balance activity (Section B) is shown as-is from the Shopee balance report; a full unpaid-order check for those months would need their SO/SGO exports too.

Sheet Cancelled & Status Check
A1: ORDER STATUS BREAKDOWN & CANCELLED-ORDER PAYOUT CHECK
A2: June 2026 orders (SO) cross-checked against 3-month Shopee balance history (SB) — verifying no payout was received for non-completed orders
A4: A. Total Orders by Status (June 2026)
A5: Order Status | B5: Unique Orders | C5: Line Items | D5: Order Value (RM, product subtotal) | E5: Orders w/ Shopee Payout Activity | F5: Net Payout Received (RM) | G5: Check Result
A6: Completed | B6: 516 | C6: 611 | D6: 16924.88 | E6: 516 | F6: 12876.41 | G6: 516/516 orders have payout records
A7: Order Received (return window open) | B7: 46 | C7: 55 | D7: 1260.96 | E7: 46 | F7: 962.61 | G7: 46/46 orders have payout records
A8: Cancelled | B8: 59 | C8: 65 | D8: 1609.47 | E8: 0 | F8: 0 | G8: PASS — no payout on any cancelled order
A9: TOTAL | B9: 621 | C9: 731 | D9: 19795.31 | F9: 13839.02
A10: Note: "Order Received (return window open)" = buyer received the parcel but can still raise a return/refund until the stated date; Shopee has already released these payouts, and they are invoiced as Completed in this workbook (matching Sitegiant).
A12: B. Cancelled Orders — Case-by-Case Check (59 orders)
A13: Order ID | B13: Order Date | C13: Order Value (RM) | D13: Cancel Reason | E13: SB Payout Activity? | F13: Net Payout (RM) | G13: Your Check (dropdown)
A14: 260601UF4RQXMP | B14: 2026-06-01 00:26 | C14: 20.9 | D14: Cancelled by buyer. Reason: Seller is not responsive to buyer's inquiries | E14: None | F14: 0 | G14: Pending Review
A15: 2606020X25MTA3 | B15: 2026-06-02 00:58 | C15: 19.7 | D15: Cancelled by seller. Reason: Out of stock | E15: None | F15: 0 | G15: Pending Review
A16: 26060210DXSVBV | B16: 2026-06-02 01:40 | C16: 17.7 | D16: Cancelled by buyer. Reason: Need to modify order | E16: None | F16: 0 | G16: Pending Review
A17: 2606022NAUA84J | B17: 2026-06-02 17:27 | C17: 14.9 | D17: Cancelled by buyer. Reason: Need to modify existing order | E17: None | F17: 0 | G17: Pending Review
A18: 2606033VXUAM9T | B18: 2026-06-03 05:16 | C18: 27.9 | D18: Cancelled by seller. Reason: Out of stock | E18: None | F18: 0 | G18: Pending Review
A19: 2606034BPNV7AN | B19: 2026-06-03 09:40 | C19: 17.7 | D19: Cancelled automatically by Shopee's system. Reason: Payment not received | E19: None | F19: 0 | G19: Pending Review
A20: 2606034K86FAMY | B20: 2026-06-03 11:55 | C20: 23.7 | D20: Cancelled automatically by Shopee's system. Reason: Payment not received | E20: None | F20: 0 | G20: Pending Review
A21: 2606035N7RW50C | B21: 2026-06-03 22:03 | C21: 17.7 | D21: Cancelled automatically by Shopee's system. Reason: Payment not received | E21: None | F21: 0 | G21: Pending Review
A22: 2606046X8VPU3D | B22: 2026-06-04 10:17 | C22: 14.9 | D22: Cancelled by buyer. Reason: Need to change delivery address | E22: None | F22: 0 | G22: Pending Review
A23: 260606AWGR85YB | B23: 2026-06-06 00:14 | C23: 20.7 | D23: Cancelled by buyer. Reason: Need to modify existing order | E23: None | F23: 0 | G23: Pending Review
A24: 260606CB4WJ1C4 | B24: 2026-06-06 13:51 | C24: 38.4 | D24: Cancelled automatically by Shopee's system. Reason: Seller did not arrange shipment on time | E24: None | F24: 0 | G24: Pending Review
A25: 260606D6T8BX3U | B25: 2026-06-06 22:06 | C25: 18.9 | D25: Cancelled automatically by Shopee's system. Reason: Payment not received | E25: None | F25: 0 | G25: Pending Review
... A72: 260630E9CW692U | B72: 2026-06-30 11:58 | C72: 14.9 | D72: Cancelled automatically by Shopee's system. Reason: Payment not received | E72: None | F72: 0 | G72: Pending Review
A73: =COUNTIF(G14:G72,"Pending Review")&" of 59 cancelled orders still pending your review" -> 59 of 59 cancelled orders still pending your review
A75: Verification method: every Order ID above was searched across the full 3-month Shopee balance report (16 Apr - 16 Jul 2026). "None" = zero transactions found for that order (as expected for a cancelled order that never shipped/completed). Any payout on a cancelled order would be flagged in red for investigation.

Sheet Claims
A1: RESELLER CLAIMS — SUBMIT CLAIM FOR CREDIT / REFUND
A2: Case On Mobile phone Accessories Store (SCON) — use this tab to submit a claim back to FRESCOONE for a specific order (wrong item, product defect, shipping/logistics issue, etc.)
A4: Order ID | B4: Description | C4: Claim ISKU | D4: Reason to Claim | E4: Image / Receipt / Proof to Claim | F4: Claim Amount (RM) | G4: Status (Reseller/Frescoone use)
G5: Pending Review
G6: Pending Review
G7: Pending Review
G8: Pending Review
G9: Pending Review
G10: Pending Review
G11: Pending Review
G12: Pending Review
G13: Pending Review
G14: Pending Review
G15: Pending Review
G16: Pending Review
... G44: Pending Review
E45: TOTAL CLAIMED (all, RM) | F45: =SUM(F5:F44) -> 0
E46: APPROVED CLAIMS TOTAL (RM) — this is what gets credited off the invoice | F46: =SUMIF(G5:G44,"Approved",F5:F44) -> 0
A48: Example (for reference only — delete or overwrite):
A49: 260617ASXPJMQF | B49: MAGNETIC FROSTED Matte/Clear PC TPU Case Oppo Reno 13 — wrong variant shipped | C49: GB-PC-QJ(MS)-Reno12-MAT/BLK | D49: Wrong item / mistake — customer ordered Black but Blue variant was fulfilled, resulting in return | E49: [attach photo / Shopee return ticket] | F49: 19.8 | G49: Example only
A51: Instructions:
A52: 1. One row per claim. Order ID and Claim ISKU should match the "Itemized Calculation" tab where applicable.
A53: 2. Reason to Claim: state clearly — e.g. wrong item shipped by Frescoone, product defect/DOA, missing parts, shipping/logistics damage, lost parcel, over-charged DSP, etc.
A54: 3. Image / Receipt / Proof to Claim: attach or reference photo evidence, Shopee return/refund ticket number, or courier claim reference.
A55: 4. Claim Amount: the RM amount being claimed back from Frescoone for this order.
A56: 5. Frescoone will review each claim and set Status to exactly "Approved", "Rejected", or leave as "Pending Review". Only rows marked "Approved" are credited off the invoice total (see "APPROVED CLAIMS TOTAL" above, which flows through to the Invoice and Summary Dashboard tabs automatically).

Sheet Summary Dashboard
A1: RESELLER INVOICE — SUMMARY DASHBOARD
A2: Case On Mobile phone Accessories Store (SCON) — Shopee Malaysia — June 2026
A4: 1. Order Reconciliation (SO vs SGO)
A5: Shopee Order Report (SO) — total line items | C5: 731
A6: Sitegiant Export (SGO) — total line items | C6: 731
A7: Unique Order IDs — SO vs SGO | C7: 621 / 621 — 100% tally
A8: Status tally — Completed | C8: 611 (SO detail) + 55 (SO return-window) = 666 | SGO Completed = 666 MATCH
A9: Status tally — Cancelled | C9: 65 (SO) = 65 (SGO) MATCH
A10: Amount tally — Product Subtotal (SO) vs product_total (SGO) | C10: RM19,795.31 vs RM19,809.11 (diff RM13.80 across 25 orders — immaterial, likely bundle/voucher reallocation rounding)
A12: 2. Order Volume & Status Breakdown (June 2026)
A13: Total unique orders — all statuses (SO) | C13: 621
A14: — Completed | C14: 516
A15: — Order Received (return window open) — invoiced as Completed | C15: 46
A16: — Cancelled (NOT invoiced; payout check: PASS, see "Cancelled & Status Check" tab) | C16: 59
A17: Total Completed order line items invoiced (SGO) | C17: 666
A18: Unique completed orders invoiced | C18: 562
A19: Line items fully priced automatically (SKU + DSP matched) | C19: 662
A20: Line items pending manual DSP entry — see "Pending DSP Entry" tab | C20: 4
A22: 3. Invoice Calculation Summary (RM) — updates live as DSP entries are keyed in
A23: Subtotal — Dropship (DSP) charges, 666 line items | C23: =SUM('Itemized Calculation'!K2:K667) -> 12941.351
A24: Shopee Ads total spend (June 2026, per Ads report) | C24: 362
A25: Shopee Ads Rebate (70% of ads spend) | C25: =C24*0.7 -> 253.4
A26: Less: Approved Claims (Claims tab) | C26: =Claims!F46 -> 0
A27: NET INVOICE AMOUNT DUE | C27: =C23-C25-C26 -> 12687.951
A29: 4. Promotion Compliance Check (reseller retail price vs our Promo Rate table)
A30: Order lines verified against SO (Shopee Original vs Deal Price)
A31: — Correct: reseller applied our specified rate | C31: 524
A32: — WRONG RATE: reseller discounted, but not at our specified rate (flagged, still charged our rate) | C32: 70
A33: — No Promotion Set: reseller did not discount at all — charged FULL DSP (no rebate given) | C33: 70
A34: — No Promo Rate on file for that ISKU | C34: 1
A35: Could not verify (no matching SO price line) | C35: 1
A36: See "Itemized Calculation" tab (columns N-O) for the row-by-row verification and legend.
A38: 5. Reseller Earning Overview (from Order-Level Summary tab)
A39: Total Shopee income received (562 orders, per SB)
A40: Total DSP charge owed to FRESCOONE (562 orders) | C40: =SUM('Order-Level Summary'!F2:F563) -> 12941.351
A41: Reseller net earning BEFORE ads (Income - DSP charge) | C41: =SUM('Order-Level Summary'!G2:G563) -> 897.669
A42: Less: Shopee Ads spend borne by reseller (30% of RM362.00 — after 70% Frescoone rebate) | C42: =-362*(1-0.7) -> -108.6
A43: RESELLER TOTAL NET EARNING (after ads rebate) | C43: =C41+C42 -> 789.069
A44: Note: the invoice already deducts the 70% ads rebate from what the reseller owes Frescoone; the remaining 30% of the ads spend is the reseller's own cost, reflected here.
A46: 6. Returns, Refunds & Payment Status
...

Sheet DSP Lookup
A1: SKU | B1: DSP Price (RM) | C1: Promo Rate (Our File)
A2: 7TREE-PC-JJ-MagicV3-BLK | B2: 49.5 | C2: 0.02
A3: 7TREE-PC-JJ-MagicV3-GRN | B3: 49.5 | C3: 0.02
A4: 7TREE-PC-JJ-MagicV3-RED | B4: 49.5 | C4: 0.02
A5: 7TREE-PC-JJ-MagicV5-BLK | B5: 49.5 | C5: 0.02
A6: 7TREE-PC-JJ-MagicV5-GLD | B6: 49.5 | C6: 0.02
A7: 7TREE-PC-JJ-MagicV5-RED | B7: 49.5 | C7: 0.02
A8: 7TREE-PC-JJ-ZFlip7-BLK | B8: 48.7 | C8: 0.02
A9: 7TREE-PC-JJ-ZFlip7-BLU | B9: 48.7 | C9: 0.02
A10: 7TREE-PC-JJ-ZFlip7-GRN | B10: 48.7 | C10: 0.02
A11: 7TREE-PC-JJ-ZFlip7-RED | B11: 48.7 | C11: 0.02
A12: 7TREE-PC-JJ-ZFold7-BLK | B12: 49.5 | C12: 0.02
A13: 7TREE-PC-JJ-ZFold7-GRN | B13: 49.5 | C13: 0.02
A14: 7TREE-PC-JJ-ZFold7-RED | B14: 49.5
A15: 7TREE-PC-PU(MS)-Magic7Pro-BLK | B15: 19.3 | C15: 0.02
A16: 7TREE-PC-PU(MS)-Magic7Pro-WHT | B16: 19.3 | C16: 0.02
A17: 7TREE-PC-PU-Magic7Pro-BLK | B17: 13.6 | C17: 0.02
A18: 7TREE-PC-PU-Magic7Pro-WHT | B18: 13.6 | C18: 0.1
A19: 7TREE-PC-SHI(MS)-HN/SMARTX9C-BLK | B19: 20.3 | C19: 0.1
A20: 7TREE-PC-SHI(MS)-HN/SMARTX9C-TP | B20: 20.3 | C20: 0.1
A21: 7TREE-PC-SHI(MS)-HN/X9C-BLK | B21: 20.3 | C21: 0.02
A22: 7TREE-PC-SHI(MS)-HN/X9C-TP | B22: 20.3 | C22: 0.02
A23: 7TREE-PC-SHI(MS)-Honor200-BLK | B23: 20.3 | C23: 0.1
A24: 7TREE-PC-SHI(MS)-Honor200-TP | B24: 20.3 | C24: 0.1
A25: 7TREE-PC-SHI(MS)-Honor200Pro-BLK | B25: 20.3 | C25: 0.02
A26: 7TREE-PC-SHI(MS)-Honor200Pro-TP | B26: 20.3 | C26: 0.02
... A179: 7TREE-PC-XF-MagicV5-RED | B179: 48.9 | C179: 0.02
A180: BG-STP-AAWU020-Ultra-BLK | B180: 10.5
A181: BG-STP-AAWU020-Ultra-CLR | B181: 10.5
A182: BG-STP-AAWU020-Ultra-GRY | B182: 10.5 | C182: 0.05
A183: BG-STP-AW186-38-BLK | B183: 6.3 | C183: 0.05
A184: BG-STP-AW186-38-BLU | B184: 6.3 | C184: 0.05
A185: BG-STP-AW186-38-GRY | B185: 6.3 | C185: 0.05
A186: BG-STP-AW186-38-PNK | B186: 6.3 | C186: 0.05
A187: BG-STP-AW186-38-STA | B187: 6.3 | C187: 0.05
A188: BG-STP-AW186-38-WHT | B188: 6.3 | C188: 0.05
A189: BG-STP-AW186-42-BLK | B189: 6.3 | C189: 0.05
A190: BG-STP-AW186-42-BLU | B190: 6.3 | C190: 0.05
A191: BG-STP-AW186-42-GRY | B191: 6.3 | C191: 0.05
A192: BG-STP-AW186-42-PNK | B192: 6.3 | C192: 0.05
...
