Workbook

Sheet Invoice
B2: FRESCOONE Trading Sdn Bhd | D2: INVOICE
B3: 202301048876 (1542790-P) | D3: Invoice No.: | E3: INV-LCON6-2026
B4: B-G-13 Block B Menara Alpha Jalan 4A/27A, | D4: Invoice Date: | E4: 19 July 2026
B5: Seksyen 2 Wangsa Maju, 53300 Kuala Lumpur | D5: Period: | E5: June 2026
B7: Bill To:
B8: Case On Mobile phone Accessories Store
B9: No 4,Taman Seri Mangga, 4,Jalan Sri Mangga
B10: Reseller Code: LCON (Lazada Malaysia storefront)
B12: Description | C12: Basis | D12: Amount (RM)
B13: DSP charges - June 2026 chargeable orders (68 orders, 88 line items), net of confirmed returns | C13: Itemized Calculation' Return-Adjusted subtotal | D13: ='Itemized Calculation'!M91
B14: Less: Approved Claims (see Claims tab) | C14: Status = Approved only | D14: ='Claims'!G43
B16: NET INVOICE AMOUNT DUE | D16: =D13-D14
B19: Payment Details
B20: Payable to: | C20: Frescoone Trading Sdn. Bhd
B21: Bank: | C21: OCBC Bank (Malaysia) Berhad
B22: Account No.: | C22: 7011620649
B24: Notes:
B25: 1. DSP = Dropship Price charged by FRESCOONE Trading Sdn Bhd to reseller for stock fulfilled via dropship.
B26: 2. Amounts reflect Completed orders for June 2026, matched via Sitegiant order export against the Lazada order report (LO), net of 1 order confirmed Returned (RM18.30 removed - see Returns & Refunds tab).
B27: 3. No advertising rebate applies to this invoice - Lazada does not have an ads-spend rebate arrangement for this store (unlike the Shopee stores).
B28: 4. See "Itemized Calculation" for the full row-by-row breakdown.
B29: 5. Return and claim credits/deductions are only applied once marked "Confirmed Good" / "Approved" on their respective tabs.

Sheet Itemized Calculation
A1: No. | B1: Order ID | C1: Marketplace Order No. | D1: Order Date | E1: SKU | F1: Product | G1: Qty | H1: DSP Price (RM) | I1: Promo Rate | J1: Applied? | K1: Final Unit Price (RM) | L1: Line Total (RM) | M1: Return-Adjusted Line Total (RM) | N1: RSP - Our Reference Retail Price (RM) | O1: Reseller's Actual Price (RM, net of checkout voucher) | P1: Actual Discount % (vs RSP) | Q1: Order Status | R1: Verification Status | S1: Note
A2: 1 | B2: 224817 | C2: 507577501164243 | D2: 2026-06-02 17:32 | E2: ZFRI-CL-CLGOR-iP16E-SLV | F2: ZIFRIEND GORILLA AR Aluminium Alloy Tempered Glass Clear Camera Lens Protector for iPhone 17 Pro Max 17e 17 Air 16E 16 15 14 13 Pro Max Plus Mini Frame Full Cover Tools Set | G2: 1 | H2: 7.7 | I2: 0.08 | J2: Yes | K2: =IF(J2="Yes",ROUND(H2*(1-I2),4),H2) | L2: =ROUND(K2*G2,2) | M2: =IF(ISNA(MATCH(B2,'Returns & Refunds'!$A$3:$A$3,0)),L2,IF(INDEX('Returns & Refunds'!$G$3:$G$3,MATCH(B2,'Returns & Refunds'!$A$3:$A$3,0))="Confirmed Good - Remove Charge",0,L2)) | N2: 12 | O2: 9.81 | P2: 0.1825 | Q2: Completed | R2: WRONG RATE
A3: 2 | B3: 224817 | C3: 507577501164243 | D3: 2026-06-02 17:32 | E3: ZFRI-SP-GOR-i13-CLR | F3: CASEON GORILLA Premium Tempered Glass CLEAR / PRIVACY / MATTE Tempered Glass For iPhone 17 Air 17e 17 Pro Max 16e 16 15 14 Plus 13 12 11 Pro Max XS Max XR Full Screen Cover Installation Tools | G3: 1 | H3: 10.5 | I3: 0.01 | J3: Yes | K3: =IF(J3="Yes",ROUND(H3*(1-I3),4),H3) | L3: =ROUND(K3*G3,2) | M3: =IF(ISNA(MATCH(B3,'Returns & Refunds'!$A$3:$A$3,0)),L3,IF(INDEX('Returns & Refunds'!$G$3:$G$3,MATCH(B3,'Returns & Refunds'!$A$3:$A$3,0))="Confirmed Good - Remove Charge",0,L3)) | N3: 15 | O3: 13.41 | P3: 0.106 | Q3: Completed | R3: WRONG RATE
A4: 3 | B4: 224818 | C4: 504293603001414 | D4: 2026-06-02 17:34 | E4: KDZ-PC-STAN-ZFlip6-BLK | F4: MAGNETIC 360 RINGSTAND Hinge Protection Clear Black Case for Samsung Galaxy Z Flip 7 6 5 Shockproof Phone Case Cover KDZ | G4: 1 | H4: 29.2 | I4: 0.08 | J4: Yes | K4: =IF(J4="Yes",ROUND(H4*(1-I4),4),H4) | L4: =ROUND(K4*G4,2) | M4: =IF(ISNA(MATCH(B4,'Returns & Refunds'!$A$3:$A$3,0)),L4,IF(INDEX('Returns & Refunds'!$G$3:$G$3,MATCH(B4,'Returns & Refunds'!$A$3:$A$3,0))="Confirmed Good - Remove Charge",0,L4)) | N4: 40 | O4: 34.86 | P4: 0.1285 | Q4: Completed | R4: WRONG RATE
A5: 4 | B5: 224843 | C5: 507579315672262 | D5: 2026-06-02 20:22 | E5: GKK-PC-UT(SP/MS)-ZFold5-BLK | F5: GKK ULTRA SLIM MATTE MAGSAFE Magnet Samsung Galaxy Z Fold 7 5 4 3 5G Lightweight Screen Cover PC Shockproof Phone Case Cover Casing | G5: 1 | H5: 24.7 | I5: 0.03 | J5: Yes | K5: =IF(J5="Yes",ROUND(H5*(1-I5),4),H5) | L5: =ROUND(K5*G5,2) | M5: =IF(ISNA(MATCH(B5,'Returns & Refunds'!$A$3:$A$3,0)),L5,IF(INDEX('Returns & Refunds'!$G$3:$G$3,MATCH(B5,'Returns & Refunds'!$A$3:$A$3,0))="Confirmed Good - Remove Charge",0,L5)) | N5: 35 | O5: 33.9 | P5: 0.0314 | Q5: Completed | R5: Correct
A6: 5 | B6: 224886 | C6: 507566747752281 | D6: 2026-06-03 00:42 | E6: GKK-PC-AIR2(SP)-ZFlip7-CLR | F6: GKK SCREEN GLASS COVER CLEAR HINGE PROTECTION Transparent Samsung Galaxy Z Flip 7 5G Full Airbag Shockproof Phone Case Casing | G6: 1 | H6: 16.9 | I6: 0.02 | J6: Yes | K6: =IF(J6="Yes",ROUND(H6*(1-I6),4),H6) | L6: =ROUND(K6*G6,2) | M6: =IF(ISNA(MATCH(B6,'Returns & Refunds'!$A$3:$A$3,0)),L6,IF(INDEX('Returns & Refunds'!$G$3:$G$3,MATCH(B6,'Returns & Refunds'!$A$3:$A$3,0))="Confirmed Good - Remove Charge",0,L6)) | N6: 25 | O6: 23.18 | P6: 0.0728 | Q6: Completed | R6: WRONG RATE
A7: 6 | B7: 224902 | C7: 504272284347534 | D7: 2026-06-03 03:43 | E7: CK-LC-MATT-MbookPro/13(16-19)-CLR/BLK | F7: MATTE PC TPU Case for MacBook Pro Air 15 13 14 16 M5 M4 M2 M3 A2340 A2341 A2992 A2991 A2681 A2485 A2442 A2251 A2289 A2338 A2159 A2179 A2337 A2779 A2780 Shockproof Case Cover Casing CK | G7: 1 | H7: 37.7 | I7: 0.05 | J7: Yes | K7: =IF(J7="Yes",ROUND(H7*(1-I7),4),H7) | L7: =ROUND(K7*G7,2) | M7: =IF(ISNA(MATCH(B7,'Returns & Refunds'!$A$3:$A$3,0)),L7,IF(INDEX('Returns & Refunds'!$G$3:$G$3,MATCH(B7,'Returns & Refunds'!$A$3:$A$3,0))="Confirmed Good - Remove Charge",0,L7)) | N7: 50 | O7: 45.03 | P7: 0.0994 | Q7: Completed | R7: WRONG RATE
A8: 7 | B8: 224943 | C8: 507553182128072 | D8: 2026-06-03 10:57 | E8: ZFRI-SP-GOR-i13-CLR | F8: CASEON GORILLA Premium Tempered Glass CLEAR / PRIVACY / MATTE Tempered Glass For iPhone 17 Air 17e 17 Pro Max 16e 16 15 14 Plus 13 12 11 Pro Max XS Max XR Full Screen Cover Installation Tools | G8: 1 | H8: 10.5 | I8: 0.01 | J8: Yes | K8: =IF(J8="Yes",ROUND(H8*(1-I8),4),H8) | L8: =ROUND(K8*G8,2) | M8: =IF(ISNA(MATCH(B8,'Returns & Refunds'!$A$3:$A$3,0)),L8,IF(INDEX('Returns & Refunds'!$G$3:$G$3,MATCH(B8,'Returns & Refunds'!$A$3:$A$3,0))="Confirmed Good - Remove Charge",0,L8)) | N8: 15 | O8: 14.9 | P8: 0.0067 | Q8: Completed | R8: Correct
A9: 8 | B9: 224949 | C9: 504298874650956 | D9: 2026-06-03 11:24 | E9: XINC-LAC-VERS-Bag/16inch-BLU/YLW | F9: PU LEATHER MICROFIBER Laptop Sleeve Bag Shockproof MousePad Case for MacBook Pro Air 13 14 15 16 Inch Notebook Waterproof Cover casing | G9: 1 | H9: 18.9 | I9: 0.01 | J9: Yes | K9: =IF(J9="Yes",ROUND(H9*(1-I9),4),H9) | L9: =ROUND(K9*G9,2) | M9: =IF(ISNA(MATCH(B9,'Returns & Refunds'!$A$3:$A$3,0)),L9,IF(INDEX('Returns & Refunds'!$G$3:$G$3,MATCH(B9,'Returns & Refunds'!$A$3:$A$3,0))="Confirmed Good - Remove Charge",0,L9)) | N9: 26 | O9: 24.32 | P9: 0.0646 | Q9: Completed | R9: WRONG RATE
A10: 9 | B10: 224954 | C10: 504265882525309 | D10: 2026-06-03 12:12 | E10: KDZ-PC-STAN-S26Ultra-TPR | F10: FROSTED MATTE CLEAR MagSafe Magnet 360 RINGSTAND Case for Samsung Galaxy S26 Ultra Plus S25 Ultra Plus S24 Ultra S24 Plus S23 Ultra Plus 5G Shockproof Phone Case Cover | G10: 1 | H10: 27.8 | I10: 0.08 | J10: Yes | K10: =IF(J10="Yes",ROUND(H10*(1-I10),4),H10) | L10: =ROUND(K10*G10,2) | M10: =IF(ISNA(MATCH(B10,'Returns & Refunds'!$A$3:$A$3,0)),L10,IF(INDEX('Returns & Refunds'!$G$3:$G$3,MATCH(B10,'Returns & Refunds'!$A$3:$A$3,0))="Confirmed Good - Remove Charge",0,L10)) | N10: 40 | O10: 36.7 | P10: 0.0825 | Q10: Completed | R10: Correct
A11: 10 | B11: 225031 | C11: 507588327220062 | D11: 2026-06-03 18:18 | E11: MXX-WTF-iP16-CLR | F11: MOXIAOXING HYDROGEL SOFT FILM Clear Privacy Matte Blueray iPhone 16 Pro Max Plus 15 Pro Max Plus 14 Pro Max Plus 13 12 11 Pro Max Mini XS Max XR X XS SE 3 8 7 6 6s Plus Full Cover Hydrogel Film Soft Screen Protector | G11: 1 | H11: 8.3 | I11: 0.3 | J11: Yes | K11: =IF(J11="Yes",ROUND(H11*(1-I11),4),H11) | L11: =ROUND(K11*G11,2) | M11: =IF(ISNA(MATCH(B11,'Returns & Refunds'!$A$3:$A$3,0)),L11,IF(INDEX('Returns & Refunds'!$G$3:$G$3,MATCH(B11,'Returns & Refunds'!$A$3:$A$3,0))="Confirmed Good - Remove Charge",0,L11)) | N11: 13.5 | O11: 12.83 | P11: 0.0496 | Q11: Completed | R11: WRONG RATE
A12: 11 | B12: 225031 | C12: 507588327220062 | D12: 2026-06-03 18:18 | E12: MXX-WTF-iP16-CLR | F12: MOXIAOXING HYDROGEL SOFT FILM Clear Privacy Matte Blueray iPhone 16 Pro Max Plus 15 Pro Max Plus 14 Pro Max Plus 13 12 11 Pro Max Mini XS Max XR X XS SE 3 8 7 6 6s Plus Full Cover Hydrogel Film Soft Screen Protector | G12: 1 | H12: 8.3 | I12: 0.3 | J12: Yes | K12: =IF(J12="Yes",ROUND(H12*(1-I12),4),H12) | L12: =ROUND(K12*G12,2) | M12: =IF(ISNA(MATCH(B12,'Returns & Refunds'!$A$3:$A$3,0)),L12,IF(INDEX('Returns & Refunds'!$G$3:$G$3,MATCH(B12,'Returns & Refunds'!$A$3:$A$3,0))="Confirmed Good - Remove Charge",0,L12)) | N12: 13.5 | O12: 12.82 | P12: 0.0504 | Q12: Completed | R12: WRONG RATE
A13: 12 | B13: 225051 | C13: 507646916522306 | D13: 2026-06-03 21:07 | E13: ZFRI-SP-GOR-i13-MAT | F13: CASEON GORILLA Premium Tempered Glass CLEAR / PRIVACY / MATTE Tempered Glass For iPhone 17 Air 17e 17 Pro Max 16e 16 15 14 Plus 13 12 11 Pro Max XS Max XR Full Screen Cover Installation Tools | G13: 1 | H13: 14.8 | I13: 0.01 | J13: Yes | K13: =IF(J13="Yes",ROUND(H13*(1-I13),4),H13) | L13: =ROUND(K13*G13,2) | M13: =IF(ISNA(MATCH(B13,'Returns & Refunds'!$A$3:$A$3,0)),L13,IF(INDEX('Returns & Refunds'!$G$3:$G$3,MATCH(B13,'Returns & Refunds'!$A$3:$A$3,0))="Confirmed Good - Remove Charge",0,L13)) | N13: 21 | O13: 20.9 | P13: 0.0048 | Q13: Completed | R13: WRONG RATE
A14: 13 | B14: 225283 | C14: 504392843299329 | D14: 2026-06-05 01:30 | E14: MXX-WTF-9.7(17)-BR | F14: CLEAR HD Hydrogel Film for iPad Pro 11 / 12.9 / Air 5 Air 4 3/ 10 Gen 10.9 9 8 7 10.2 /Pro 10.5 Air 2 / Pro 9.7 / Mini 7 6 5 4 Clear / Anti Bluelight Full Cover Hydrogel Film Soft Screen Protector | G14: 1 | H14: 9.9 | I14: 0.3 | J14: Yes | K14: =IF(J14="Yes",ROUND(H14*(1-I14),4),H14) | L14: =ROUND(K14*G14,2) | M14: =IF(ISNA(MATCH(B14,'Returns & Refunds'!$A$3:$A$3,0)),L14,IF(INDEX('Returns & Refunds'!$G$3:$G$3,MATCH(B14,'Returns & Refunds'!$A$3:$A$3,0))="Confirmed Good - Remove Charge",0,L14)) | N14: 15 | O14: 10.4 | P14: 0.3067 | Q14: Completed | R14: WRONG RATE
A15: 14 | B15: 225409 | C15: 507739561536573 | D15: 2026-06-05 18:03 | E15: DUX-PC-FLIP-S24FE-BLK | F15: DUX DUCIS SKIN PRO Flip Case Samsung Galaxy S26 Ultra Plus S25 Edge Ultra Plus S24 FE S24 Ultra S21 FE 5G / Ultra / Plus Magnetic Leather Flip Stand Card Slot Holder Shockproof Bumper Phone Case Cover Casing | G15: 1 | H15: 18.3 | I15: 0.2 | J15: Yes | K15: =IF(J15="Yes",ROUND(H15*(1-I15),4),H15) | L15: =ROUND(K15*G15,2) | M15: =IF(ISNA(MATCH(B15,'Returns & Refunds'!$A$3:$A$3,0)),L15,IF(INDEX('Returns & Refunds'!$G$3:$G$3,MATCH(B15,'Returns & Refunds'!$A$3:$A$3,0))="Confirmed Good - Remove Charge",0,L15)) | N15: 25 | O15: 19.9 | P15: 0.204 | Q15: Returned | R15: Correct | S15: Flagged Returned by Lazada - see Returns & Refunds tab
A16: 15 | B16: 225497 | C16: 504506230120250 | D16: 2026-06-06 00:02 | E16: ZFRI-SP-XGO-i17-PVC | F16: CASEON X-GORILLA CLEAR / PRIVACY Tempered Glass For iPhone 17 Pro Max Air 17e 16E 16 Pro Max 16 Plus 15 Pro Max 14 Pro Max 15 Plus 13 Pro Max 12 Pro Max Full Screen Cover Screen Protector | G16: 1 | H16: 11.8 | I16: 0.05 | J16: Yes | K16: =IF(J16="Yes",ROUND(H16*(1-I16),4),H16) | L16: =ROUND(K16*G16,2) | M16: =IF(ISNA(MATCH(B16,'Returns & Refunds'!$A$3:$A$3,0)),L16,IF(INDEX('Returns & Refunds'!$G$3:$G$3,MATCH(B16,'Returns & Refunds'!$A$3:$A$3,0))="Confirmed Good - Remove Charge",0,L16)) | N16: 18 | O16: 16.15 | P16: 0.1028 | Q16: Completed | R16: WRONG RATE
A17: 16 | B17: 225530 | C17: 504517651220283 | D17: 2026-06-06 03:09 | E17: ZFRI-SP-GOR-i15-PVC | F17: CASEON GORILLA Premium Tempered Glass CLEAR / PRIVACY / MATTE Tempered Glass For iPhone 17 Air 17e 17 Pro Max 16e 16 15 14 Plus 13 12 11 Pro Max XS Max XR Full Screen Cover Installation Tools | G17: 1 | H17: 13.2 | I17: 0.01 | J17: Yes | K17: =IF(J17="Yes",ROUND(H17*(1-I17),4),H17) | L17: =ROUND(K17*G17,2) | M17: =IF(ISNA(MATCH(B17,'Returns & Refunds'!$A$3:$A$3,0)),L17,IF(INDEX('Returns & Refunds'!$G$3:$G$3,MATCH(B17,'Returns & Refunds'!$A$3:$A$3,0))="Confirmed Good - Remove Charge",0,L17)) | N17: 18 | O17: 17.7 | P17: 0.0167 | Q17: Completed | R17: WRONG RATE
A18: 17 | B18: 225555 | C18: 504532077608923 | D18: 2026-06-06 09:31 | E18: DUX-SP-2.5D-TabS10Plus-CLR | F18: DUX DUCIS CLEAR HD 2.5D Tempered Glass Samsung Galaxy Tab A11 A9 S10 FE Plus S10 Ultra A9 Plus S9 FE Plus S9 Ultra A8 10.5 S8 Ultra Plus A7 Lite 8.7 A7 10.4 S7 Plus S7 FE S6 Lite A 10.1 Full Screen Cover Tempered Glass Protector | G18: 1 | H18: 30.3 | I18: 0.2 | J18: Yes | K18: =IF(J18="Yes",ROUND(H18*(1-I18),4),H18) | L18: =ROUND(K18*G18,2) | M18: =IF(ISNA(MATCH(B18,'Returns & Refunds'!$A$3:$A$3,0)),L18,IF(INDEX('Returns & Refunds'!$G$3:$G$3,MATCH(B18,'Returns & Refunds'!$A$3:$A$3,0))="Confirmed Good - Remove Charge",0,L18)) | N18: 48 | O18: 30.15 | P18: 0.3719 | Q18: Completed | R18: WRONG RATE
A19: 18 | B19: 225579 | C19: 507822575691167 | D19: 2026-06-06 12:13 | E19: KDZ-PC-DDR-i16Pro-BLK | F19: FROSTED MATTE CLEAR Magnet 360 RINGSTAND Case For iPhone 16 Pro Max Plus 15 Pro Max Plus 14 Pro Max 13 Pro Max Plus Shockproof Phone Case Cover KDZ | G19: 1 | H19: 27.2 | I19: 0.25 | J19: Yes | K19: =IF(J19="Yes",ROUND(H19*(1-I19),4),H19) | L19: =ROUND(K19*G19,2) | M19: =IF(ISNA(MATCH(B19,'Returns & Refunds'!$A$3:$A$3,0)),L19,IF(INDEX('Returns & Refunds'!$G$3:$G$3,MATCH(B19,'Returns & Refunds'!$A$3:$A$3,0))="Confirmed Good - Remove Charge",0,L19)) | N19: 38 | O19: 26.98 | P19: 0.29 | Q19: Completed | R19: WRONG RATE
A20: 19 | B20: 225584 | C20: 504550869396235 | D20: 2026-06-06 12:35 | E20: XINC-LAC-VERS-Bag/15.4inch-BLU/YLW | F20: PU LEATHER MICROFIBER Laptop Sleeve Bag Shockproof MousePad Case for MacBook Pro Air 13 14 15 16 Inch Notebook Waterproof Cover casing | G20: 1 | H20: 18.1 | I20: 0.01 | J20: Yes | K20: =IF(J20="Yes",ROUND(H20*(1-I20),4),H20) | L20: =ROUND(K20*G20,2) | M20: =IF(ISNA(MATCH(B20,'Returns & Refunds'!$A$3:$A$3,0)),L20,IF(INDEX('Returns & Refunds'!$G$3:$G$3,MATCH(B20,'Returns & Refunds'!$A$3:$A$3,0))="Confirmed Good - Remove Charge",0,L20)) | N20: 25 | O20: 24.7 | P20: 0.012 | Q20: Completed | R20: Correct
A21: 20 | B21: 225627 | C21: 504617439924482 | D21: 2026-06-06 18:36 | E21: DDC-LC-CRYS-MbookAir/13(18)-CLR | F21: CRYSTAL HARD PC CASE For MacBook Pro Air 15 13 14 16 M5 M4 M2 M3 M2 M1 A3240 A3241 A2991 A2992 A2941 A2779 A2780 A2681 A2485 A2442 A2251 A2289 A2338 A2159 A2179 A2337 A1932 Hard PC Shockproof Protective Case Cover Casing FREE Keyboard Cover | G21: 1 | H21: 24.2 | I21: 0.05 | J21: Yes | K21: =IF(J21="Yes",ROUND(H21*(1-I21),4),H21) | L21: =ROUND(K21*G21,2) | M21: =IF(ISNA(MATCH(B21,'Returns & Refunds'!$A$3:$A$3,0)),L21,IF(INDEX('Returns & Refunds'!$G$3:$G$3,MATCH(B21,'Returns & Refunds'!$A$3:$A$3,0))="Confirmed Good - Remove Charge",0,L21)) | N21: 35 | O21: 34.9 | P21: 0.0029 | Q21: Completed | R21: WRONG RATE
A22: 21 | B22: 225627 | C22: 504617439924482 | D22: 2026-06-06 18:36 | E22: DDC-LC-CRYS-MbookAir/13(18)-CLR | F22: CRYSTAL HARD PC CASE For MacBook Pro Air 15 13 14 16 M5 M4 M2 M3 M2 M1 A3240 A3241 A2991 A2992 A2941 A2779 A2780 A2681 A2485 A2442 A2251 A2289 A2338 A2159 A2179 A2337 A1932 Hard PC Shockproof Protective Case Cover Casing FREE Keyboard Cover | G22: 1 | H22: 24.2 | I22: 0.05 | J22: Yes | K22: =IF(J22="Yes",ROUND(H22*(1-I22),4),H22) | L22: =ROUND(K22*G22,2) | M22: =IF(ISNA(MATCH(B22,'Returns & Refunds'!$A$3:$A$3,0)),L22,IF(INDEX('Returns & Refunds'!$G$3:$G$3,MATCH(B22,'Returns & Refunds'!$A$3:$A$3,0))="Confirmed Good - Remove Charge",0,L22)) | N22: 35 | O22: 34.9 | P22: 0.0029 | Q22: Completed | R22: WRONG RATE
A23: 22 | B23: 225627 | C23: 504617439924482 | D23: 2026-06-06 18:36 | E23: DDC-LC-CRYS-MbookPro/16(21)-CLR | F23: CRYSTAL HARD PC CASE For MacBook Pro Air 15 13 14 16 M5 M4 M2 M3 M2 M1 A3240 A3241 A2991 A2992 A2941 A2779 A2780 A2681 A2485 A2442 A2251 A2289 A2338 A2159 A2179 A2337 A1932 Hard PC Shockproof Protective Case Cover Casing FREE Keyboard Cover | G23: 1 | H23: 24.4 | I23: 0.05 | J23: Yes | K23: =IF(J23="Yes",ROUND(H23*(1-I23),4),H23) | L23: =ROUND(K23*G23,2) | M23: =IF(ISNA(MATCH(B23,'Returns & Refunds'!$A$3:$A$3,0)),L23,IF(INDEX('Returns & Refunds'!$G$3:$G$3,MATCH(B23,'Returns & Refunds'!$A$3:$A$3,0))="Confirmed Good - Remove Charge",0,L23)) | N23: 35 | O23: 33.2 | P23: 0.0514 | Q23: Completed | R23: Correct
A24: 23 | B24: 225770 | C24: 507943992326407 | D24: 2026-06-07 12:37 | E24: ZFRI-CL-CLGOR-i17Pro-ORG | F24: ZIFRIEND GORILLA AR Aluminium Alloy Tempered Glass Clear Camera Lens Protector for iPhone 17 Pro Max 17e 17 Air 16E 16 15 14 13 Pro Max Plus Mini Frame Full Cover Tools Set | G24: 1 | H24: 12.4 | I24: 0.08 | J24: Yes | K24: =IF(J24="Yes",ROUND(H24*(1-I24),4),H24) | L24: =ROUND(K24*G24,2) | M24: =IF(ISNA(MATCH(B24,'Returns & Refunds'!$A$3:$A$3,0)),L24,IF(INDEX('Returns & Refunds'!$G$3:$G$3,MATCH(B24,'Returns & Refunds'!$A$3:$A$3,0))="Confirmed Good - Remove Charge",0,L24)) | N24: 20 | O24: 18.3 | P24: 0.085 | Q24: Completed | R24: WRONG RATE
A25: 24 | B25: 225880 | C25: 507993313274463 | D25: 2026-06-07 21:48 | E25: DDC-LC-MATT-Surface3(S)-BLK | F25: MATTE PC Case Microsoft Surface Laptop 7 Go 5 4 3 2 1 15 12.4 13.5 13.8 15 2036 2037 1868 1951 1867 1958 1950 Hard Pc Case Cover Casing | G25: 1 | H25: 27.1 | I25: 0.05 | J25: Yes | K25: =IF(J25="Yes",ROUND(H25*(1-I25),4),H25) | L25: =ROUND(K25*G25,2) | M25: =IF(ISNA(MATCH(B25,'Returns & Refunds'!$A$3:$A$3,0)),L25,IF(INDEX('Returns & Refunds'!$G$3:$G$3,MATCH(B25,'Returns & Refunds'!$A$3:$A$3,0))="Confirmed Good - Remove Charge",0,L25)) | N25: 40 | O25: 37.9 | P25: 0.0525 | Q25: Completed | R25: Correct
A26: 25 | B26: 225984 | C26: 508019552738755 | D26: 2026-06-08 10:30 | E26: KDZ-PC-STAN-S24Ultra-TPR | F26: FROSTED MATTE CLEAR MagSafe Magnet 360 RINGSTAND Case for Samsung Galaxy S26 Ultra Plus S25 Ultra Plus S24 Ultra S24 Plus S23 Ultra Plus 5G Shockproof Phone Case Cover | G26: 1 | H26: 28.6 | I26: 0.08 | J26: Yes | K26: =IF(J26="Yes",ROUND(H26*(1-I26),4),H26) | L26: =ROUND(K26*G26,2) | M26: =IF(ISNA(MATCH(B26,'Returns & Refunds'!$A$3:$A$3,0)),L26,IF(INDEX('Returns & Refunds'!$G$3:$G$3,MATCH(B26,'Returns & Refunds'!$A$3:$A$3,0))="Confirmed Good - Remove Charge",0,L26)) | N26: 40 | O26: 34.86 | P26: 0.1285 | Q26: Completed | R26: WRONG RATE
A27: 26 | B27: 226121 | C27: 508071911725334 | D27: 2026-06-08 21:54 | E27: GKK-PC-STAND-MagicV3-SLV | F27: GKK MAGNETIC ULTRA THIN Matte PC Slim Honor Magic V3 Lightweight Full Screen Cover Shockproof Phone Case Cover Casing | G27: 1 | H27: 46.7 | I27: 0.03 | J27: Yes | K27: =IF(J27="Yes",ROUND(H27*(1-I27),4),H27) | L27: =ROUND(K27*G27,2) | M27: =IF(ISNA(MATCH(B27,'Returns & Refunds'!$A$3:$A$3,0)),L27,IF(INDEX('Returns & Refunds'!$G$3:$G$3,MATCH(B27,'Returns & Refunds'!$A$3:$A$3,0))="Confirmed Good - Remove Charge",0,L27)) | N27: 65 | O27: 63 | P27: 0.0308 | Q27: Completed | R27: Correct
... A89: 88 | B89: 229751 | C89: 509200564368556 | D89: 2026-06-30 22:13 | E89: SONG-MAC-ROU-Set-BLK | F89: SONG FASHION Phone CROSSBODY Lanyard Universal Neck Strap Mini Patch Clip Set and Wrist Tether Key Chain Holder Universal for All Smart Phone Case 1cm Thickness for All Smartphones Patch Clip Tether Tab Hanger | G89: 1 | H89: 17.9 | I89: 0.35 | J89: Yes | K89: =IF(J89="Yes",ROUND(H89*(1-I89),4),H89) | L89: =ROUND(K89*G89,2) | M89: =IF(ISNA(MATCH(B89,'Returns & Refunds'!$A$3:$A$3,0)),L89,IF(INDEX('Returns & Refunds'!$G$3:$G$3,MATCH(B89,'Returns & Refunds'!$A$3:$A$3,0))="Confirmed Good - Remove Charge",0,L89)) | N89: 28 | O89: 17.19 | P89: 0.3861 | Q89: Completed | R89: WRONG RATE
K91: SUBTOTAL (Line Total): | L91: =SUM(L2:L89) | M91: =SUM(M2:M89)
A93: Legend (Verification Status):
A94: Correct | B94: Reseller's actual selling price (net of any checkout voucher) is discounted from our RSP by the exact table rate - charged DSP x (1 - table rate).
A95: WRONG RATE | B95: Reseller is discounting from RSP, but not at the agreed table rate - still charged at table rate (compliance flag only).
A96: No Promotion Set | B96: Table has a promo rate on file, but reseller's actual price matches RSP (no discount at all) - charged full DSP.
A97: No LO Match / No Promo Rate On File / No RSP On File | B97: Could not verify against Lazada order export, or SKU has no rate/RSP on file - falls back to table rate if one exists, else full DSP.
A98: Order Status = Returned | B98: Flagged - see Returns & Refunds tab; Return-Adjusted Line Total auto-zeroes once confirmed.

Sheet Order-Level Summary
A1: No. | B1: Order ID | C1: Marketplace Order No. | D1: Order Date | E1: Income Received (RM, Lazada LB) | F1: Total DSP Charge (Return-Adjusted, RM) | G1: Reseller Final Earning (RM)
A2: 1 | B2: 224817 | C2: 507577501164243 | D2: 2026-06-02 17:32 | E2: 17.95 | F2: =SUMIF('Itemized Calculation'!C:C,C2,'Itemized Calculation'!M:M) | G2: =E2-F2
A3: 2 | B3: 224818 | C3: 504293603001414 | D3: 2026-06-02 17:34 | E3: 27.33 | F3: =SUMIF('Itemized Calculation'!C:C,C3,'Itemized Calculation'!M:M) | G3: =E3-F3
A4: 3 | B4: 224843 | C4: 507579315672262 | D4: 2026-06-02 20:22 | E4: 24.61 | F4: =SUMIF('Itemized Calculation'!C:C,C4,'Itemized Calculation'!M:M) | G4: =E4-F4
A5: 4 | B5: 224886 | C5: 507566747752281 | D5: 2026-06-03 00:42 | E5: 18.11 | F5: =SUMIF('Itemized Calculation'!C:C,C5,'Itemized Calculation'!M:M) | G5: =E5-F5
A6: 5 | B6: 224902 | C6: 504272284347534 | D6: 2026-06-03 03:43 | E6: 35.78 | F6: =SUMIF('Itemized Calculation'!C:C,C6,'Itemized Calculation'!M:M) | G6: =E6-F6
A7: 6 | B7: 224943 | C7: 507553182128072 | D7: 2026-06-03 10:57 | E7: 10.66 | F7: =SUMIF('Itemized Calculation'!C:C,C7,'Itemized Calculation'!M:M) | G7: =E7-F7
A8: 7 | B8: 224949 | C8: 504298874650956 | D8: 2026-06-03 11:24 | E8: 19.2 | F8: =SUMIF('Itemized Calculation'!C:C,C8,'Itemized Calculation'!M:M) | G8: =E8-F8
A9: 8 | B9: 224954 | C9: 504265882525309 | D9: 2026-06-03 12:12 | E9: 26.74 | F9: =SUMIF('Itemized Calculation'!C:C,C9,'Itemized Calculation'!M:M) | G9: =E9-F9
A10: 9 | B10: 225031 | C10: 507588327220062 | D10: 2026-06-03 18:18 | E10: 20.09 | F10: =SUMIF('Itemized Calculation'!C:C,C10,'Itemized Calculation'!M:M) | G10: =E10-F10
A11: 10 | B11: 225051 | C11: 507646916522306 | D11: 2026-06-03 21:07 | E11: 15.04 | F11: =SUMIF('Itemized Calculation'!C:C,C11,'Itemized Calculation'!M:M) | G11: =E11-F11
A12: 11 | B12: 225283 | C12: 504392843299329 | D12: 2026-06-05 01:30 | E12: 7.39 | F12: =SUMIF('Itemized Calculation'!C:C,C12,'Itemized Calculation'!M:M) | G12: =E12-F12
A13: 12 | B13: 225409 | C13: 507739561536573 | D13: 2026-06-05 18:03 | E13: 0 | F13: =SUMIF('Itemized Calculation'!C:C,C13,'Itemized Calculation'!M:M) | G13: =E13-F13
... A69: 68 | B69: 229751 | C69: 509200564368556 | D69: 2026-06-30 22:13 | E69: 13.47 | F69: =SUMIF('Itemized Calculation'!C:C,C69,'Itemized Calculation'!M:M) | G69: =E69-F69
D71: TOTAL: | E71: =SUM(E2:E69) | F71: =SUM(F2:F69) | G71: =SUM(G2:G69)

Sheet Returns & Refunds
A1: A. JUNE 2026 ORDERS FLAGGED "RETURNED" BY LAZADA (verified against Lazada Income Overview / LB wallet ledger)
A2: Order ID | B2: Order Status (Sitegiant/Lazada) | C2: SKU | D2: Product Name | E2: Qty | F2: DSP Charged (RM) | G2: Decision | H2: DSP Charge Removed (RM) | I2: Evidence / Notes
A3: 225409 | B3: Returned | C3: DUX-PC-FLIP-S24FE-BLK | D3: DUX DUCIS SKIN PRO Flip Case Samsung Galaxy S26 Ultra Plus S25 Edge Ultra Plus S24 FE S24 Ultra S21 FE 5G / Ultra / Plus Magnetic Leather Flip Stand Card Slot Holder Shockproof Bumper Phone Case Cover Casing | E3: 1 | F3: =IFERROR(SUMIF('Itemized Calculation'!B:B,A3,'Itemized Calculation'!L:L),0) | G3: Confirmed Good - Remove Charge | H3: =IF(G3="Confirmed Good - Remove Charge",F3,0) | I3: LB wallet ledger shows net income of RM0.00 for this order - full reversal (Item Price, Commission, Payment Fee, LazCoins Discount all reversed). Return confirmed, charge removed.
H5: =SUM(H3:H3)
A7: B. PAYMENT STATUS CHECK (Lazada Income Overview / LB wallet ledger)
A8: All 68 chargeable June orders (Completed + Returned) matched a wallet transaction in the Lazada Income Overview report (100% payout check PASS).
A9: 10 orders were Cancelled in Lazada this period (excluded from invoice entirely).
A10: No separate Shopee-style Ads Rebate applies to this reseller - Lazada does not have an ads-spend file in the source data set for this store.

Sheet Claims
A1: CLAIMS - key in any claim the reseller is making against this invoice. Set Status to "Approved" once verified - only Approved rows count toward the deduction.
A2: Order ID | B2: Description | C2: Claim ISKU | D2: Reason to Claim | E2: Image Receipt | F2: Proof to Claim | G2: Claim Amount (RM) | H2: Status
H3: Pending Review
H4: Pending Review
H5: Pending Review
H6: Pending Review
H7: Pending Review
H8: Pending Review
H9: Pending Review
H10: Pending Review
H11: Pending Review
H12: Pending Review
H13: Pending Review
H14: Pending Review
... H42: Pending Review
A43: APPROVED CLAIMS TOTAL (Status = Approved only): | G43: =SUMIF(H3:H42,"Approved",G3:G42)
A44: TOTAL CLAIMED (all rows, incl. pending/rejected): | G44: =SUM(G3:G42)

Sheet Summary Dashboard
A1: FRESCOONE x Case On Mobile phone Accessories Store (LCON) - June 2026 SUMMARY DASHBOARD
A3: 1. RECONCILIATION (LO vs SGO)
A4: Lazada (LO) unique orders matched | C4: 78
A5: Sitegiant (SGO) unique orders | C5: 78
A6: Match result | C6: 78/78 tally (PASS)
A8: 2. VOLUME
A9: Chargeable line items this invoice (Completed + Returned) | C9: 88
A10: Priced lines | C10: 88
A11: Pending manual DSP entry | C11: 0
A12: Cancelled orders (Lazada, excluded) | C12: 10
A13: Unique chargeable orders | C13: 68
A15: 3. INVOICE CALCULATION
A16: Subtotal (DSP charge, return-adjusted) | C16: ='Invoice'!D13
A17: Less: Approved Claims | C17: =-'Invoice'!D14
A18: NET INVOICE AMOUNT DUE | C18: ='Invoice'!D16
A20: 4. PROMO COMPLIANCE
A21: Correct | C21: 34
A22: WRONG RATE | C22: 53
A23: No Promotion Set | C23: 1
A25: 5. EARNING OVERVIEW (Reseller side, informational)
A26: Total Lazada income received (all chargeable orders) | C26: 1546.17
A27: Total DSP charged (this invoice, return-adjusted) | C27: ='Invoice'!D13
A28: Reseller net earning | C28: =C26-C27
A30: 6. RETURNS / PAYMENT STATUS
A31: Orders flagged Returned by Lazada | C31: 1
A32: Confirmed returns (charge removed) | C32: 1
A33: Payout check (all chargeable orders matched an LB income txn) | C33: PASS - 68/68
A35: 7. ACTION NEEDED
A36: Pending DSP Entry - 0 line(s) need a manual DSP price (none this batch)
A37: Claims - review and mark Status = Approved/Rejected as needed
A38: Returns & Refunds - 1 confirmed return already auto-applied; re-check if reseller disputes.

Sheet DSP Lookup
A1: SKU | B1: DSP Price (RM) | C1: Promo Rate (Our File)
A2: 7TREE-PC-JJ-MagicV3-BLK | B2: 49.5 | C2: 0.02
A3: 7TREE-PC-JJ-MagicV3-GRN | B3: 49.5 | C3: 0.02
A4: 7TREE-PC-JJ-MagicV3-RED | B4: 49.5 | C4: 0.02
A5: 7TREE-PC-JJ-MagicV5-BLK | B5: 49.5 | C5: 0.02
A6: 7TREE-PC-JJ-MagicV5-GLD | B6: 49.5 | C6: 0.02
A7: 7TREE-PC-JJ-MagicV5-RED | B7: 49.5 | C7: 0.02
A8: 7TREE-PC-JJ-ZFlip7-BLK | B8: 48.7 | C8: 0.02
A9: 7TREE-PC-JJ-ZFlip7-BLU | B9: 48.7 | C9: 0.02
A10: 7TREE-PC-JJ-ZFlip7-GRN | B10: 48.7 | C10: 0.02
A11: 7TREE-PC-JJ-ZFlip7-RED | B11: 48.7 | C11: 0.02
A12: 7TREE-PC-JJ-ZFold7-BLK | B12: 49.5 | C12: 0.02
A13: 7TREE-PC-JJ-ZFold7-GRN | B13: 49.5 | C13: 0.02
A14: 7TREE-PC-JJ-ZFold7-RED | B14: 49.5
A15: 7TREE-PC-PU(MS)-Magic7Pro-BLK | B15: 19.3 | C15: 0.02
A16: 7TREE-PC-PU(MS)-Magic7Pro-WHT | B16: 19.3 | C16: 0.02
A17: 7TREE-PC-PU-Magic7Pro-BLK | B17: 13.6 | C17: 0.02
A18: 7TREE-PC-PU-Magic7Pro-WHT | B18: 13.6 | C18: 0.1
A19: 7TREE-PC-SHI(MS)-HN/SMARTX9C-BLK | B19: 20.3 | C19: 0.1
A20: 7TREE-PC-SHI(MS)-HN/SMARTX9C-TP | B20: 20.3 | C20: 0.1
A21: 7TREE-PC-SHI(MS)-HN/X9C-BLK | B21: 20.3 | C21: 0.02
A22: 7TREE-PC-SHI(MS)-HN/X9C-TP | B22: 20.3 | C22: 0.02
A23: 7TREE-PC-SHI(MS)-Honor200-BLK | B23: 20.3 | C23: 0.1
A24: 7TREE-PC-SHI(MS)-Honor200-TP | B24: 20.3 | C24: 0.1
A25: 7TREE-PC-SHI(MS)-Honor200Pro-BLK | B25: 20.3 | C25: 0.02
A26: 7TREE-PC-SHI(MS)-Honor200Pro-TP | B26: 20.3 | C26: 0.02
... A179: 7TREE-PC-XF-MagicV5-RED | B179: 48.9 | C179: 0.02
A180: BG-STP-AAWU020-Ultra-BLK | B180: 10.5
A181: BG-STP-AAWU020-Ultra-CLR | B181: 10.5
A182: BG-STP-AAWU020-Ultra-GRY | B182: 10.5 | C182: 0.05
A183: BG-STP-AW186-38-BLK | B183: 6.3 | C183: 0.05
A184: BG-STP-AW186-38-BLU | B184: 6.3 | C184: 0.05
A185: BG-STP-AW186-38-GRY | B185: 6.3 | C185: 0.05
A186: BG-STP-AW186-38-PNK | B186: 6.3 | C186: 0.05
A187: BG-STP-AW186-38-STA | B187: 6.3 | C187: 0.05
A188: BG-STP-AW186-38-WHT | B188: 6.3 | C188: 0.05
A189: BG-STP-AW186-42-BLK | B189: 6.3 | C189: 0.05
A190: BG-STP-AW186-42-BLU | B190: 6.3 | C190: 0.05
A191: BG-STP-AW186-42-GRY | B191: 6.3 | C191: 0.05
A192: BG-STP-AW186-42-PNK | B192: 6.3 | C192: 0.05
...
